Workbook
Name _1._Sürdürülebilir_Kampüs_Faaliyetlerinin_Desteklenmesi: '1-Devamsızlık Formu (Ek-4)'!$BJ$2:$BJ$7
Name _1__Ağaçlandırma_ve_peyzaj_düzenleme_faaliyetlerinin_desteklenmesi: '1-Devamsızlık Formu (Ek-4)'!$BJ$3:$BJ$7
Name _2._Kampüs_Altyapı_ve_Bakım_Faaliyetlerinin_Desteklenmesi: '1-Devamsızlık Formu (Ek-4)'!$BK$2:$BK$4
Name _3._Sosyal_ve_Kültürel_Faaliyetlerin_Desteklenmesi: '1-Devamsızlık Formu (Ek-4)'!$BL$2:$BL$7
Name _4._Akademik_ve_İdari_Faaliyetlerin_Desteklenmesi: '1-Devamsızlık Formu (Ek-4)'!$BM$2:$BM$5
Name _5._Toplumsal_Hizmet_ve_İşbirliği_Faaliyetlerinin_Desteklenmesi: '1-Devamsızlık Formu (Ek-4)'!$BN$2:$BN$6
Name _6._Öğrenci_Gelişim_ve_Uyum_Faaliyetlerinin_Desteklenmesi: '1-Devamsızlık Formu (Ek-4)'!$BO$2:$BO$5
Name _7._Dijital_Dönüşüm_ve_İnovasyon_Faaliyetlerinin_Desteklenmesi: '1-Devamsızlık Formu (Ek-4)'!$BP$2:$BP$4
Name _8._Girişimcilik_Ekosistemi_Faaliyetlerinin_Desteklenmesi: '1-Devamsızlık Formu (Ek-4)'!$BQ$2:$BQ$4
Name ak: '1-Devamsızlık Formu (Ek-4)'!$BJ$15:$BJ$17
Name di: '1-Devamsızlık Formu (Ek-4)'!$BJ$25:$BJ$26
Name gi: '1-Devamsızlık Formu (Ek-4)'!$BJ$27:$BJ$28
Name ka: '1-Devamsızlık Formu (Ek-4)'!$BJ$8:$BJ$9
Name öğ: '1-Devamsızlık Formu (Ek-4)'!$BJ$22:$BJ$24
Name s: '1-Devamsızlık Formu (Ek-4)'!$BJ$3:$BJ$7
Name so: '1-Devamsızlık Formu (Ek-4)'!$BJ$10:$BJ$14
Name sü: '1-Devamsızlık Formu (Ek-4)'!$BJ$3:$BJ$7
Name to: '1-Devamsızlık Formu (Ek-4)'!$BJ$18:$BJ$21

Sheet !!! VERİLER !!!
B1: CEP HARÇLIĞI TUTARI | C1: 1375 | K1: ASGARİ GEÇİM İNDİRİMİ YILIN İLK ALTI AYI İÇİN BELİRLENEN ASGARİ ÜCRET TUTARI GİRİLEREK GÜNCELLENECEK
B2: Kısa Vadeli Sigorta Kolları Primi | C2: 0.01 | E2: Genel Sağlık Sigortası Primi | F2: 0.045
B4: İŞ YERİ UNVANI | C4: GAZİANTEP REKTÖRLÜĞÜ | G4: PROGRAM PORTAL NUMARASINI ALTA YAZINIZ | K4: ASGARİ GEÇİM İNDİRİMİNE ESAS BRÜT ASGARİ ÜCRET
B5: İŞ YERİ İMZA YETKİLİSİ ADI SOYADI | C5: Mehmet Fatih EVYAPAN | D5: İŞ YERİ İMZA YETKİLİSİ UNVANI | E5: Daire Başkanı | O5: İŞKUR Gençlik Programı
B6: PROJE KOORDİNATÖRÜ ADI SOYADI | C6: Mehmet Bereket TATAR | D6: KOORDİNATÖR UNVANI | E6: Şube Müdürü | K6: 0.15 | L6: 20002.5 | M6: =L6*12 -> 240030 | O6: Ağaçlandırma faaliyetlerinin desteklenmesi
B7: İŞ YERİ SGK SİCİL NUMARASI | C7: 385400101122832602709-30/000 | K7: 1 | L7: BEKAR | M7: =ROUND(M6*N7*K6/12,2) -> 1500.19 | N7: 0.5 | O7: Geri dönüşüm ve atık imha faaliyetlerinin desteklenmesi | Q7: ADANA
B8: İŞ YERİ BANKA HESAP NUMARASI | C8: TR310001200133800004000406 | K8: 2 | L8: EVLİ EŞİ ÇALIŞAN | M8: =ROUND(M6*K6*N8/12,2) -> 1500.19 | N8: 0.5 | O8: Biyolojik çeşitliliğin korunması ve doğal yaşam alanlarının restorasyon faaliyetlerinin desteklenmesi | Q8: ADIYAMAN
B9: İŞ YERİ BANKA ŞUBESİ | C9: T.C. HALK BANKASI | E9: ÜNİVERSİTE UYDU ŞUBESİ | G9: 13324 | K9: 3 | L9: EVLİ EŞİ ÇALIŞAN 1 ÇOCUKLU | M9: =ROUND(M6*N9*K6/12,2) -> 1725.22 | N9: 0.575 | O9: Çocuk bakım işlerine yönelik faaliyetlerin desteklenmesi | Q9: AFYON
B10: İŞ YERİ Adresi | C10: GAZİANTEP Üniversitesi | K10: 4 | L10: EVLİ EŞİ ÇALIŞAN 2 ÇOCUKLU | M10: =ROUND(M6*K6*N10/12,2) -> 1950.24 | N10: 0.65 | O10: Engelli, yaşlı ve hasta bakımına yönelik faaliyetlerin desteklenmesi | Q10: AĞRI
B11: İŞ YERİ Telefon Numarası | C11: 0342 360 14 51 | K11: 5 | L11: EVLİ EŞİ ÇALIŞAN 3 ÇOCUKLU | M11: =ROUND(M6*N11*K6/12,2) -> 2250.28 | N11: 0.75 | O11: Tarımsal Üretim Uygulamaları ve Hayvancılık Faaliyetlerinin Desteklenmesi | Q11: AKSARAY
B12: İŞ YERİ Fax Numarası | C12: 0342 360 10 13 | G12: Sözleşme Tarihi | K12: 6 | L12: EVLİ EŞİ ÇALIŞAN 4 ÇOCUKLU | M12: =ROUND(M6*K6*N12/12,2) -> 2400.3 | N12: 0.8 | O12: Kamusal Alanların Temizlik, Bakım ve Onarım Faaliyetlerinin Desteklenmesi | Q12: AMASYA
B13: İŞ YERİ Eposta Adresi | C13: sksdb@gantep.edu.tr | G13: 30.10.2025 | K13: 7 | L13: EVLİ EŞİ ÇALIŞAN 5 ÇOCUKLU | M13: =ROUND(M6*K6*N13/12,2) -> 2550.32 | N13: 0.85 | O13: Spor ve kültür faaliyetlerinin desteklenmesi | Q13: ANKARA
B14: Program Başlama Tarihi | C14: 17.11.2025 | G14: Sözleşme No | K14: 8 | L14: EVLİ EŞİ ÇALIŞMAYAN | M14: =ROUND(M6*N14*K6/12,2) -> 1800.23 | N14: 0.6 | O14: Parkların ve yeşil alanların korunması ve geliştirilmesi faaliyetlerinin desteklenmesi | Q14: ANTALYA
B15: Program Bitiş Tarihi | C15: 30.06.2026 | G15: 2025/4 | K15: 9 | L15: EVLİ EŞİ ÇALIŞMAYAN 1 ÇOCUKLU | M15: =ROUND(M6*N15*K6/12,2) -> 2025.25 | N15: 0.675 | O15: Toplum sağlığı ve hijyen faaliyetlerinin desteklenmesi | Q15: ARDAHAN
B16: Program Konusu | C16: İŞKUR Gençlik Programı | K16: 10 | L16: EVLİ EŞİ Ç ALIŞMAYAN 2 ÇOCUKLU | M16: =ROUND(M6*N16*K6/12,2) -> 2250.28 | N16: 0.75 | O16: Kırsal Kalkınma ve Köy Projelerinin Desteklenmesi | Q16: ARTVİN
B17: Program Yürütülen İL | C17: GAZİANTEP | K17: 11 | L17: EVLİ EŞİ ÇALIŞMAYAN 3 ÇOCUKLU | M17: =ROUND(M6*K6*N17/12,2) -> 2550.32 | N17: 0.85 | O17: Afet hazırlık faaliyetlerinin desteklenmesi | Q17: AYDIN
B18: T.C. / Vergi Kimlik No | C18: 6110026286 | K18: 12 | L18: ENGELLİ İNDİRİMİ 1. DERECE | O18: Çevresel kirliliğin önlenmesi ve iyileştirme faaliyetlerinin desteklenmesi | Q18: BALIKESİR
B19: NOT: ASGARİ GEÇİM İNDİRİMİ KATILIMCI LİSTESİNE; SAYFANIN SAĞINDA YAZAN BİLGİYE GÖRE GİRİLECEK OLUP, YEVMİYE SAYISINA GÖRE OTOMATİK HESAPLANACAKTIR. | K19: 13 | L19: ENGELLİ İNDİRİMİ 2. DERECE | Q19: BARTIN
K20: 14 | L20: ENGELLİ İNDİRİMİ 3. DERECE | Q20: BATMAN
Q21: BAYBURT
B22: !!!! BU SAYFADAN ÇIKTI ALINMAYACAK !!!! | Q22: BİLECİK
Q23: BİNGÖL
Q24: BİTLİS
Q25: BOLU
Q26: BURDUR
Q27: BURSA
Q28: ÇANAKKALE
Q29: ÇANKIRI
Q30: ÇORUM
Q31: DENİZLİ
Q32: DİYARBAKIR
Q33: DÜZCE
Q34: EDİRNE
... Q87: ZONGULDAK

Sheet !!!KATILIMCI LİSTESİ!!!
B1: ADI SOYADI | C1: T.C.KİMLİK NUMARASI | D1: BANKA HESAP NO
A2: 1 | B2: ABDÜLAZİZ BÜYÜKDEMİR | C2: 11231264864 | D2: TR300001200133800001193050
A3: 2 | B3: ABDULBAKİ DALGIN | C3: 51664708658 | D3: TR410001200133800001186450
A4: 3 | B4: ABDULBASİT YİLMAZ | C4: 12980258364 | D4: TR390001200133800001206274
A5: 4 | B5: ABDULKADİR AKÇAKOCA | C5: 10244285118 | D5: TR590001200133800001190879
A6: 5 | B6: ABDULKADİR ALPASLAN | C6: 47248051944 | D6: TR720001200133800001183370
A7: 6 | B7: ABDULKADİR EKİNCİ | C7: 30554505850 | D7: TR050001200133800001141896
A8: 7 | B8: ABDULKADİR TAŞPINAR | C8: 11576369514 | D8: TR470001200133800001209525
A9: 8 | B9: ABDULKADİR ÜSTÜNER | C9: 32120360108 | D9: TR070001200133800001196859 | E9: DİKKAT: KATILIMCI LİSTESİNİ ALFABETİK SIRALADIKTAN SONRA DEVAMSIZLIK FORMUNU GİRİNİZ. AKSİ HALDE KAYMA DOLAYISIYLA ÖDEMELER KARIŞABİLİR.
A10: 9 | B10: ABDÜLKADİR DÜK | C10: 46378087250 | D10: TR900001200133800001148999
A11: 10 | B11: ABDULLAH BİNGÖL | C11: 36059043460 | D11: TR120001200968500001052505
A12: 11 | B12: ABDULLAH ÇALIŞKAN | C12: 17987044460 | D12: TR120001200133800001183383
A13: 12 | B13: ABDULLAH İŞ | C13: 47635631308 | D13: TR490001200133800001179807
A14: 13 | B14: ABDULLAH ULUN | C14: 10850337096 | D14: TR350001200133800001192281
A15: 14 | B15: ABDULLAH YÜZGEÇ | C15: 13802183994 | D15: TR260001200133800001186720
A16: 15 | B16: ABDULSAMET KAYA | C16: 12734216152 | D16: TR310004601256888000151249
A17: 16 | B17: ABDULSAMET ÖZDEMİR | C17: 34354480898 | D17: TR830001200133800001199662
A18: 17 | B18: ABDULSAMET YAŞAR | C18: 12021022954 | D18: TR720001200133800001178811
A19: 18 | B19: ABDÜLVEKİL GÖK | C19: 12179215468 | D19: TR120001200133800001209476
A20: 19 | B20: ABDURRAHMAN YAVUZ | C20: 11516080912 | D20: TR430001009010737450905001
A21: 20 | B21: ABDURRAHMAN EMRE COŞKUN | C21: 58198589036 | D21: TR550001200133800001171357
... A1499: 1498 | B1499: ZÜMRÜT CEYLAN | C1499: 11060346304 | D1499: TR210001009010539326905001
A1500: 1499
A1501: 1500
A1502: 1501
A1503: 1502
A1504: 1503
A1505: 1504
A1506: 1505
A1507: 1506
A1508: 1507
A1509: 1508
A1510: 1509
A1511: 1510
... A3001: 3000

Sheet Üst Yazı
BA10: T.C.
BA14: …………………………………………………..
A15: Antet Evrak Sayısı Manuel Girilecektir
BA18: …………………………………………………..
BA28: Sayı : | BI28: …………….. | EE28: =TODAY() -> 46205
BA32: Konu : | BI32: ="İŞKUR Gençlik Programı Katılımcı Ücretleri ("&'!!! VERİLER !!!'!G9&")" -> İŞKUR Gençlik Programı Katılımcı Ücretleri (13324)
BA40: ÇALIŞMA VE İŞ KURUMU İL MÜDÜRLÜĞÜNE
DB44: ='!!! VERİLER !!!'!C17 -> GAZİANTEP
BA52: =" Kurumumuz ile İl Müdürlüğünüz arasında "&'!!! VERİLER !!!'!C14&"-"&'!!! VERİLER !!!'!C15& " tarihleri arasında işbirliği kapsamında düzenlenen İŞKUR Gençlik Programının "&'1-Devamsızlık Formu (Ek-4)'!P1&" "&'1-Devamsızlık Formu (Ek-4)'!C1&" dönemine ait hak ediş belgeleri yazımız ekinde olup, belirtilen tutarın aşağıda bilgileri verilen banka hesabımıza aktarılması hususunda;" -> Kurumumuz ile İl Müdürlüğünüz arasında 17.11.2025-30.06.2026 tarihleri arasında işbirliği kapsamında düzenlenen İŞKUR Gençlik Programının HAZİRAN 2026 dönemine ait hak ediş belgeleri yazımız ekinde olup, belirtilen tutarın aşağıda bilgileri verilen banka hesabımıza aktarılması hususunda;
BA69: Gereğini arz/rica ederim.
DF80: ='!!! VERİLER !!!'!C5 -> Mehmet Fatih EVYAPAN
DF84: ='!!! VERİLER !!!'!E5 -> Daire Başkanı
BA93: ='!!! VERİLER !!!'!C9 -> T.C. HALK BANKASI
BA97: Şube : | BL97: ='!!! VERİLER !!!'!E9 -> ÜNİVERSİTE UYDU ŞUBESİ
BA101: IBAN No : | BL101: ='!!! VERİLER !!!'!C8 -> TR310001200133800004000406
BA110: Program Portal No | BH110: Katılımcı Sayısı | BN110: Toplam Çalışma Gün Sayısı | BW110: Kısa Vadeli Sigorta Kolları Primi | CG110: Genel Sağlık Sigortası Primi | CP110: SGK Prim Toplamı | DA110: Katılımcılar İçin Net Ele Geçen | DJ110: İcra Kesintisi | DT110: Katrılımcılar İçin Ödenecek Ücret Toplamı | EE110: Hakediş Toplamı
BA121: ='!!! VERİLER !!!'!G9 -> 13324 | BH121: ='2-Bordro'!H2 -> 1482 | BN121: ='2-Bordro'!F3005 -> 17864 | BW121: ='2-Bordro'!H3005 -> 245630 | CG121: ='2-Bordro'!N3005 -> 1105335 | CP121: ='2-Bordro'!O3005 -> 1350965 | DA121: ='2-Bordro'!R3005 -> 24563000 | DJ121: ='2-Bordro'!Q3005 -> 0 | DT121: ='2-Bordro'!G3005 -> 24563000 | EE121: ='2-Bordro'!P3005 -> 25913965
BA131: EKLER
BA136: 1- Katılımcı Devamsızlık formu (1 adet, … sayfa),
BA140: 2- Katılımcı Devam ücret bordrosu (1 adet, … sayfa).
BA144: 3- Harcama Talimatı (1 adet, 1 sayfa)
BA148: 4- Banka Listesi (1 adet, ... sayfa)
BA177: ='!!! VERİLER !!!'!C10 -> GAZİANTEP Üniversitesi | CE177: ='!!! VERİLER !!!'!C11 -> 0342 360 14 51 | DI177: ='!!! VERİLER !!!'!C13 -> sksdb@gantep.edu.tr
CE182: ='!!! VERİLER !!!'!C12 -> 0342 360 10 13

Sheet 1-Devamsızlık Formu (Ek-4)
A1: Ait Olduğu Yıl | C1: 2026 | J1: Ait Olduğu Ay | P1: HAZİRAN | AI1: Ödenecek Yevmiye Sayısı | AJ1: ██ | AK1: İşe girmeden önceki ve İşten ayrıldıktan sonraki günlerin zemin rengi grileştirilecek. Tatil günleri boş kalacak. | BB1: ÇALIŞTIĞI GÜNLER (BOŞ KALACAK)
A2: İŞKUR Gençlik Programı No | J2: İŞKUR Gençlik Program Konusu | AJ2: Ü | AK2: Ücretsiz izin alan katılımcılar için seçilecek | BA2: ██ | BB2: İşe girmeden önceki ve İşten ayrıldıktan sonraki günler ile çalışmadığı günler için girilecek. Resmi ve idari tatillerde de bu kullanılacak. | BI2: ANA FAALİYET | BJ2: ALT FAALİYET
A3: İŞKUR Gençlik Program Başlama Tarihi | J3: İŞKUR Gençlik Program Bitiş Tarihi | AJ3: S | AK3: Rapor alan katılımcılar için seçilecek | BA3: İ | BB3: İZİN (ÜCRETSİZ) | BI3: 1. Sürdürülebilir Kampüs Faaliyetlerinin Desteklenmesi | BJ3: 1) Ağaçlandırma ve peyzaj düzenleme faaliyetlerinin desteklenmesi | BK3: 1. Sürdürülebilir Kampüs Faaliyetlerinin Desteklenmesi | BL3: sü
A4: Yüklenici Adı | J4: Yüklenici Yetkilisi Ad, Soyad | AJ4: M | AK4: Mazeret izni alan katılımcılar için seçilecek | AT4: 1 | AU4: OCAK | AV4: 2024 | AX4: FAALİYET ALANI | AY4: ALT FAALİYET ALANI | BA4: S | BB4: SAĞLIK RAPORU | BI4: 1. Sürdürülebilir Kampüs Faaliyetlerinin Desteklenmesi | BJ4: 2) Geri dönüşüm, atık yönetimi ve sıfır atık projelerinin desteklenmesi | BK4: 2. Kampüs Altyapı ve Bakım Faaliyetlerinin Desteklenmesi | BL4: ka
A5: Katılımcı Bilgileri | D5: Günler | AJ5: İ | AK5: İş Kazası nedeniyle izin alan katılımcılar için seçilecek | AT5: 2 | AU5: ŞUBAT | AV5: 2025 | BA5: İK | BB5: İŞ KAZASI VE MESLEK HASTALIĞI | BI5: 1. Sürdürülebilir Kampüs Faaliyetlerinin Desteklenmesi | BJ5: 3) Biyolojik çeşitliliğin korunması ve doğal yaşam alanlarının restorasyon faaliyetlerinin desteklenmesi | BK5: 3. Sosyal ve Kültürel Faaliyetlerin Desteklenmesi | BL5: so
A6: Sıra | B6: TC Kimlik No | C6: Ad Soyad | D6: 1 | E6: 2 | F6: 3 | G6: 4 | H6: 5 | I6: 6 | J6: 7 | K6: 8 | L6: 9 | M6: 10 | N6: 11 | O6: 12 | P6: 13 | Q6: 14 | R6: 15 | S6: 16 | T6: 17 | U6: 18 | V6: 19 | W6: 20 | X6: 21 | Y6: 22 | Z6: 23 | AA6: 24 | AB6: 25 | AC6: 26 | AD6: 27 | AE6: 28 | AF6: =IF(P1=AU5,"-",29) -> 29 | AG6: =IF(P1=AU5,"-",30) -> 30 | AH6: =IF(P1=AU4,AP7,IF(P1=AU5,AS7,IF(P1=AU6,AP7,IF(P1=AU7,AS7,IF(P1=AU8,AP7,IF(P1=AU9,AS7,IF(P1=AU10,AP7,IF(P1=AU11,AP7,IF(P1=AU12,AS7,IF(P1=AU13,AP7,IF(P1=AU14,AS7,IF(P1=AU15,AP7,)))))))))))) -> - | AJ6: D | AK6: Mazeretsiz işe gelmeyen katılımcılar için seçilecek. | AT6: 3 | AU6: MART | BA6: MG | BB6: MAZERETSİZ GELMEME | BI6: 1. Sürdürülebilir Kampüs Faaliyetlerinin Desteklenmesi | BJ6: 4) Enerji verimliliği projelerinin desteklenmesi | BK6: 4. Akademik ve İdari Faaliyetlerin Desteklenmesi | BL6: ak
A7: 1 | B7: 11231264864 | C7: ABDÜLAZİZ BÜYÜKDEMİR | G7: ██ | H7: ██ | I7: ██ | J7: ██ | N7: ██ | O7: ██ | P7: ██ | Q7: ██ | U7: ██ | V7: ██ | W7: ██ | X7: ██ | AB7: ██ | AC7: ██ | AD7: ██ | AE7: ██ | AI7: =COUNTBLANK(D7:AG7) -> 14 | AJ7: =IF(B7>10000000,AI7,0) -> 14 | AK7: =AO7-AN7 -> 0 | AM7: =MONTH(AW7) -> 6 | AN7: =COUNTA(D7:AH7) -> 30 | AO7: =IF(AM7=1,AP7,IF(AM7=2,AR7,IF(AM7=3,AP7,IF(AM7=4,AQ7,IF(AM7=5,AP7,IF(AM7=6,AQ7,IF(AM7=7,AP7,IF(AM7=8,AP7,IF(AM7=9,AQ7,IF(AM7=10,AP7,IF(AM7=11,AQ7,IF(AM7=12,AP7)))))))))))) -> 30 | AP7: 31 | AQ7: 30 | AR7: 28 | AS7: - | AT7: 4 | AU7: NİSAN | AW7: =CONCATENATE(P1,AS1,C1) -> HAZİRAN 2026 | AZ7: =VLOOKUP(AX7,$BK$3:$BL$10,2,FALSE) -> #N/A | BA7: M | BB7: MAZERETLİ (HÜKÜMLÜ/TUTUKLU/GÖZALTI) | BI7: 1. Sürdürülebilir Kampüs Faaliyetlerinin Desteklenmesi | BJ7: 5) Su tasarrufu ve yağmur suyu hasadı projelerinin desteklenmesi | BK7: 5. Toplumsal Hizmet ve İşbirliği Faaliyetlerinin Desteklenmesi | BL7: to
A8: 2 | B8: 51664708658 | C8: ABDULBAKİ DALGIN | D8: ██ | E8: ██ | I8: ██ | J8: ██ | N8: ██ | O8: ██ | P8: ██ | Q8: ██ | U8: ██ | V8: ██ | W8: ██ | X8: ██ | AB8: ██ | AC8: ██ | AD8: ██ | AE8: ██ | AI8: =COUNTBLANK(D8:AG8) -> 14 | AJ8: =IF(B8>10000000,AI8,0) -> 14 | AK8: =AO8-AN8 -> 0 | AL8: ██ | AM8: =MONTH(AW8) -> 6 | AN8: =COUNTA(D8:AH8) -> 30 | AO8: =IF(AM8=1,AP8,IF(AM8=2,AR8,IF(AM8=3,AP8,IF(AM8=4,AQ8,IF(AM8=5,AP8,IF(AM8=6,AQ8,IF(AM8=7,AP8,IF(AM8=8,AP8,IF(AM8=9,AQ8,IF(AM8=10,AP8,IF(AM8=11,AQ8,IF(AM8=12,AP8)))))))))))) -> 30 | AP8: 31 | AQ8: 30 | AR8: 28 | AT8: 5 | AU8: MAYIS | AW8: =$AW$7 -> HAZİRAN 2026 | AZ8: =VLOOKUP(AX8,$BK$3:$BL$10,2,FALSE) -> #N/A | BA8: İD | BB8: İDARİ İZİN | BI8: 2. Kampüs Altyapı ve Bakım Faaliyetlerinin Desteklenmesi | BJ8: 1) Engelsiz kampüs uygulamalarının desteklenmesi | BK8: 6. Öğrenci Gelişim ve Uyum Faaliyetlerinin Desteklenmesi | BL8: öğ
A9: 3 | B9: 12980258364 | C9: ABDULBASİT YİLMAZ | D9: ██ | H9: ██ | I9: ██ | J9: ██ | K9: ██ | O9: ██ | P9: ██ | Q9: ██ | R9: ██ | V9: ██ | W9: ██ | X9: ██ | Y9: ██ | Z9: İ | AA9: İ | AB9: İ | AC9: ██ | AD9: ██ | AE9: ██ | AI9: =COUNTBLANK(D9:AG9) -> 11 | AJ9: =IF(B9>10000000,AI9,0) -> 11 | AK9: =AO9-AN9 -> 0 | AL9: İ | AM9: =MONTH(AW9) -> 6 | AN9: =COUNTA(D9:AH9) -> 30 | AO9: =IF(AM9=1,AP9,IF(AM9=2,AR9,IF(AM9=3,AP9,IF(AM9=4,AQ9,IF(AM9=5,AP9,IF(AM9=6,AQ9,IF(AM9=7,AP9,IF(AM9=8,AP9,IF(AM9=9,AQ9,IF(AM9=10,AP9,IF(AM9=11,AQ9,IF(AM9=12,AP9)))))))))))) -> 30 | AP9: 31 | AQ9: 30 | AR9: 28 | AT9: 6 | AU9: HAZİRAN | AW9: =$AW$7 -> HAZİRAN 2026 | AZ9: =VLOOKUP(AX9,$BK$3:$BL$10,2,FALSE) -> #N/A | BA9: G | BB9: PROGRAMA GEÇ BAŞLADI | BI9: 2. Kampüs Altyapı ve Bakım Faaliyetlerinin Desteklenmesi | BJ9: 2) Kampüs bilgi sistemleri ve teknolojik altyapının desteklenmesi | BK9: 7. Dijital Dönüşüm ve İnovasyon Faaliyetlerinin Desteklenmesi | BL9: di
A10: 4 | B10: 10244285118 | C10: ABDULKADİR AKÇAKOCA | G10: ██ | H10: ██ | I10: ██ | J10: ██ | N10: ██ | O10: ██ | P10: ██ | Q10: ██ | U10: ██ | V10: ██ | W10: ██ | X10: ██ | AB10: ██ | AC10: ██ | AD10: ██ | AE10: ██ | AI10: =COUNTBLANK(D10:AG10) -> 14 | AJ10: =IF(B10>10000000,AI10,0) -> 14 | AK10: =AO10-AN10 -> 0 | AL10: S | AM10: =MONTH(AW10) -> 6 | AN10: =COUNTA(D10:AH10) -> 30 | AO10: =IF(AM10=1,AP10,IF(AM10=2,AR10,IF(AM10=3,AP10,IF(AM10=4,AQ10,IF(AM10=5,AP10,IF(AM10=6,AQ10,IF(AM10=7,AP10,IF(AM10=8,AP10,IF(AM10=9,AQ10,IF(AM10=10,AP10,IF(AM10=11,AQ10,IF(AM10=12,AP10)))))))))))) -> 30 | AP10: 31 | AQ10: 30 | AR10: 28 | AT10: 7 | AU10: TEMMUZ | AW10: =$AW$7 -> HAZİRAN 2026 | AZ10: =VLOOKUP(AX10,$BK$3:$BL$10,2,FALSE) -> #N/A | BA10: KK | BB10: Kurum Kapalı Günü | BI10: 3. Sosyal ve Kültürel Faaliyetlerin Desteklenmesi | BJ10: 1) Spor ve rekreasyon faaliyetlerinin desteklenmesi | BK10: 8. Girişimcilik Ekosistemi Faaliyetlerinin Desteklenmesi | BL10: gi
A11: 5 | B11: 47248051944 | C11: ABDULKADİR ALPASLAN | G11: ██ | H11: ██ | I11: ██ | J11: ██ | N11: ██ | O11: ██ | P11: ██ | Q11: ██ | U11: ██ | V11: ██ | W11: ██ | X11: ██ | AB11: ██ | AC11: ██ | AD11: ██ | AE11: ██ | AI11: =COUNTBLANK(D11:AG11) -> 14 | AJ11: =IF(B11>10000000,AI11,0) -> 14 | AK11: =AO11-AN11 -> 0 | AL11: İK | AM11: =MONTH(AW11) -> 6 | AN11: =COUNTA(D11:AH11) -> 30 | AO11: =IF(AM11=1,AP11,IF(AM11=2,AR11,IF(AM11=3,AP11,IF(AM11=4,AQ11,IF(AM11=5,AP11,IF(AM11=6,AQ11,IF(AM11=7,AP11,IF(AM11=8,AP11,IF(AM11=9,AQ11,IF(AM11=10,AP11,IF(AM11=11,AQ11,IF(AM11=12,AP11)))))))))))) -> 30 | AP11: 31 | AQ11: 30 | AR11: 28 | AT11: 8 | AU11: AĞUSTOS | AW11: =$AW$7 -> HAZİRAN 2026 | AZ11: =VLOOKUP(AX11,$BK$3:$BL$10,2,FALSE) -> #N/A | BI11: 3. Sosyal ve Kültürel Faaliyetlerin Desteklenmesi | BJ11: 2) Kültür-sanat etkinliklerinin organizasyonunun desteklenmesi
A12: 6 | B12: 30554505850 | C12: ABDULKADİR EKİNCİ | D12: ██ | H12: ██ | I12: ██ | J12: ██ | K12: ██ | M12: ██ | P12: ██ | Q12: ██ | U12: ██ | V12: ██ | W12: ██ | X12: ██ | AB12: ██ | AC12: ██ | AD12: ██ | AE12: ██ | AI12: =COUNTBLANK(D12:AG12) -> 14 | AJ12: =IF(B12>10000000,AI12,0) -> 14 | AK12: =AO12-AN12 -> 0 | AL12: MG | AM12: =MONTH(AW12) -> 6 | AN12: =COUNTA(D12:AH12) -> 30 | AO12: =IF(AM12=1,AP12,IF(AM12=2,AR12,IF(AM12=3,AP12,IF(AM12=4,AQ12,IF(AM12=5,AP12,IF(AM12=6,AQ12,IF(AM12=7,AP12,IF(AM12=8,AP12,IF(AM12=9,AQ12,IF(AM12=10,AP12,IF(AM12=11,AQ12,IF(AM12=12,AP12)))))))))))) -> 30 | AP12: 31 | AQ12: 30 | AR12: 28 | AT12: 9 | AU12: EYLÜL | AW12: =$AW$7 -> HAZİRAN 2026 | AZ12: =VLOOKUP(AX12,$BK$3:$BL$10,2,FALSE) -> #N/A | BI12: 3. Sosyal ve Kültürel Faaliyetlerin Desteklenmesi | BJ12: 3) Öğrenci kulüp ve topluluk faaliyetlerinin desteklenmesi
A13: 7 | B13: 11576369514 | C13: ABDULKADİR TAŞPINAR | G13: ██ | H13: ██ | I13: ██ | J13: ██ | N13: ██ | O13: ██ | P13: ██ | Q13: ██ | R13: ██ | S13: ██ | T13: ██ | U13: ██ | V13: ██ | W13: ██ | X13: ██ | Y13: ██ | Z13: ██ | AA13: ██ | AB13: ██ | AC13: ██ | AD13: ██ | AE13: ██ | AF13: ██ | AG13: ██ | AI13: =COUNTBLANK(D13:AG13) -> 6 | AJ13: =IF(B13>10000000,AI13,0) -> 6 | AK13: =AO13-AN13 -> 0 | AL13: M | AM13: =MONTH(AW13) -> 6 | AN13: =COUNTA(D13:AH13) -> 30 | AO13: =IF(AM13=1,AP13,IF(AM13=2,AR13,IF(AM13=3,AP13,IF(AM13=4,AQ13,IF(AM13=5,AP13,IF(AM13=6,AQ13,IF(AM13=7,AP13,IF(AM13=8,AP13,IF(AM13=9,AQ13,IF(AM13=10,AP13,IF(AM13=11,AQ13,IF(AM13=12,AP13)))))))))))) -> 30 | AP13: 31 | AQ13: 30 | AR13: 28 | AT13: 10 | AU13: EKİM | AW13: =$AW$7 -> HAZİRAN 2026 | AZ13: =VLOOKUP(AX13,$BK$3:$BL$10,2,FALSE) -> #N/A | BI13: 3. Sosyal ve Kültürel Faaliyetlerin Desteklenmesi | BJ13: 4) Sosyal sorumluluk projelerinin desteklenmesi
A14: 8 | B14: 32120360108 | C14: ABDULKADİR ÜSTÜNER | G14: ██ | H14: ██ | I14: ██ | J14: ██ | N14: ██ | O14: ██ | P14: ██ | Q14: ██ | U14: ██ | V14: ██ | W14: ██ | X14: ██ | Y14: İ | Z14: İ | AA14: İ | AB14: ██ | AC14: ██ | AD14: ██ | AE14: ██ | AF14: İ | AG14: MG | AI14: =COUNTBLANK(D14:AG14) -> 9 | AJ14: =IF(B14>10000000,AI14,0) -> 9 | AK14: =AO14-AN14 -> 0 | AL14: İD | AM14: =MONTH(AW14) -> 6 | AN14: =COUNTA(D14:AH14) -> 30 | AO14: =IF(AM14=1,AP14,IF(AM14=2,AR14,IF(AM14=3,AP14,IF(AM14=4,AQ14,IF(AM14=5,AP14,IF(AM14=6,AQ14,IF(AM14=7,AP14,IF(AM14=8,AP14,IF(AM14=9,AQ14,IF(AM14=10,AP14,IF(AM14=11,AQ14,IF(AM14=12,AP14)))))))))))) -> 30 | AP14: 31 | AQ14: 30 | AR14: 28 | AT14: 11 | AU14: KASIM | AW14: =$AW$7 -> HAZİRAN 2026 | AZ14: =VLOOKUP(AX14,$BK$3:$BL$10,2,FALSE) -> #N/A | BI14: 3. Sosyal ve Kültürel Faaliyetlerin Desteklenmesi | BJ14: 5) Uluslararası öğrenci entegrasyon programlarının desteklenmesi
A15: 9 | B15: 46378087250 | C15: ABDÜLKADİR DÜK | G15: ██ | H15: ██ | I15: ██ | J15: ██ | N15: ██ | O15: ██ | P15: ██ | Q15: ██ | U15: ██ | V15: ██ | W15: ██ | X15: ██ | AB15: ██ | AC15: ██ | AD15: ██ | AE15: ██ | AI15: =COUNTBLANK(D15:AG15) -> 14 | AJ15: =IF(B15>10000000,AI15,0) -> 14 | AK15: =AO15-AN15 -> 0 | AL15: G | AM15: =MONTH(AW15) -> 6 | AN15: =COUNTA(D15:AH15) -> 30 | AO15: =IF(AM15=1,AP15,IF(AM15=2,AR15,IF(AM15=3,AP15,IF(AM15=4,AQ15,IF(AM15=5,AP15,IF(AM15=6,AQ15,IF(AM15=7,AP15,IF(AM15=8,AP15,IF(AM15=9,AQ15,IF(AM15=10,AP15,IF(AM15=11,AQ15,IF(AM15=12,AP15)))))))))))) -> 30 | AP15: 31 | AQ15: 30 | AR15: 28 | AT15: 12 | AU15: ARALIK | AW15: =$AW$7 -> HAZİRAN 2026 | AZ15: =VLOOKUP(AX15,$BK$3:$BL$10,2,FALSE) -> #N/A | BI15: 4. Akademik ve İdari Faaliyetlerin Desteklenmesi | BJ15: 1) Kütüphane ve Dokümantasyon Faaliyetle
A16: 10 | B16: 36059043460 | C16: ABDULLAH BİNGÖL | G16: ██ | H16: ██ | I16: ██ | J16: ██ | N16: ██ | O16: ██ | P16: ██ | Q16: ██ | U16: ██ | V16: ██ | W16: ██ | X16: ██ | AB16: ██ | AC16: ██ | AD16: ██ | AE16: ██ | AI16: =COUNTBLANK(D16:AG16) -> 14 | AJ16: =IF(B16>10000000,AI16,0) -> 14 | AK16: =AO16-AN16 -> 0 | AL16: KK | AM16: =MONTH(AW16) -> 6 | AN16: =COUNTA(D16:AH16) -> 30 | AO16: =IF(AM16=1,AP16,IF(AM16=2,AR16,IF(AM16=3,AP16,IF(AM16=4,AQ16,IF(AM16=5,AP16,IF(AM16=6,AQ16,IF(AM16=7,AP16,IF(AM16=8,AP16,IF(AM16=9,AQ16,IF(AM16=10,AP16,IF(AM16=11,AQ16,IF(AM16=12,AP16)))))))))))) -> 30 | AP16: 31 | AQ16: 30 | AR16: 28 | AT16: 13 | AW16: =$AW$7 -> HAZİRAN 2026 | AZ16: =VLOOKUP(AX16,$BK$3:$BL$10,2,FALSE) -> #N/A | BI16: 4. Akademik ve İdari Faaliyetlerin Desteklenmesi | BJ16: 2) Laboratuvar ve Araştırma Faaliyetleri
A17: 11 | B17: 17987044460 | C17: ABDULLAH ÇALIŞKAN | G17: ██ | H17: ██ | I17: ██ | J17: ██ | N17: ██ | O17: ██ | P17: ██ | Q17: ██ | U17: ██ | V17: ██ | W17: ██ | X17: ██ | AB17: ██ | AC17: ██ | AD17: ██ | AE17: ██ | AF17: MG | AG17: MG | AI17: =COUNTBLANK(D17:AG17) -> 12 | AJ17: =IF(B17>10000000,AI17,0) -> 12 | AK17: =AO17-AN17 -> 0 | AM17: =MONTH(AW17) -> 6 | AN17: =COUNTA(D17:AH17) -> 30 | AO17: =IF(AM17=1,AP17,IF(AM17=2,AR17,IF(AM17=3,AP17,IF(AM17=4,AQ17,IF(AM17=5,AP17,IF(AM17=6,AQ17,IF(AM17=7,AP17,IF(AM17=8,AP17,IF(AM17=9,AQ17,IF(AM17=10,AP17,IF(AM17=11,AQ17,IF(AM17=12,AP17)))))))))))) -> 30 | AP17: 31 | AQ17: 30 | AR17: 28 | AT17: 14 | AW17: =$AW$7 -> HAZİRAN 2026 | AZ17: =VLOOKUP(AX17,$BK$3:$BL$10,2,FALSE) -> #N/A | BI17: 4. Akademik ve İdari Faaliyetlerin Desteklenmesi | BJ17: 3) İdari Birim Faaliyetleri
A18: 12 | B18: 47635631308 | C18: ABDULLAH İŞ | G18: ██ | H18: ██ | I18: ██ | J18: ██ | N18: ██ | O18: ██ | P18: ██ | Q18: ██ | R18: İ | S18: İ | T18: İ | U18: ██ | V18: ██ | W18: ██ | X18: ██ | Y18: ██ | Z18: ██ | AA18: ██ | AB18: ██ | AC18: ██ | AD18: ██ | AE18: ██ | AF18: ██ | AG18: ██ | AI18: =COUNTBLANK(D18:AG18) -> 6 | AJ18: =IF(B18>10000000,AI18,0) -> 6 | AK18: =AO18-AN18 -> 0 | AM18: =MONTH(AW18) -> 6 | AN18: =COUNTA(D18:AH18) -> 30 | AO18: =IF(AM18=1,AP18,IF(AM18=2,AR18,IF(AM18=3,AP18,IF(AM18=4,AQ18,IF(AM18=5,AP18,IF(AM18=6,AQ18,IF(AM18=7,AP18,IF(AM18=8,AP18,IF(AM18=9,AQ18,IF(AM18=10,AP18,IF(AM18=11,AQ18,IF(AM18=12,AP18)))))))))))) -> 30 | AP18: 31 | AQ18: 30 | AR18: 28 | AT18: 15 | AW18: =$AW$7 -> HAZİRAN 2026 | AZ18: =VLOOKUP(AX18,$BK$3:$BL$10,2,FALSE) -> #N/A | BI18: 5. Toplumsal Hizmet ve İşbirliği Faaliyetlerinin Desteklenmesi | BJ18: 1) Toplum sağlığı ve rehberlik faaliyetlerinin desteklenmesi
A19: 13 | B19: 10850337096 | C19: ABDULLAH ULUN | G19: ██ | H19: ██ | I19: ██ | J19: ██ | N19: ██ | O19: ██ | P19: ██ | Q19: ██ | U19: ██ | V19: ██ | W19: ██ | X19: ██ | AB19: ██ | AC19: ██ | AD19: ██ | AE19: ██ | AF19: İ | AG19: İ | AI19: =COUNTBLANK(D19:AG19) -> 12 | AJ19: =IF(B19>10000000,AI19,0) -> 12 | AK19: =AO19-AN19 -> 0 | AM19: =MONTH(AW19) -> 6 | AN19: =COUNTA(D19:AH19) -> 30 | AO19: =IF(AM19=1,AP19,IF(AM19=2,AR19,IF(AM19=3,AP19,IF(AM19=4,AQ19,IF(AM19=5,AP19,IF(AM19=6,AQ19,IF(AM19=7,AP19,IF(AM19=8,AP19,IF(AM19=9,AQ19,IF(AM19=10,AP19,IF(AM19=11,AQ19,IF(AM19=12,AP19)))))))))))) -> 30 | AP19: 31 | AQ19: 30 | AR19: 28 | AT19: 16 | AW19: =$AW$7 -> HAZİRAN 2026 | AZ19: =VLOOKUP(AX19,$BK$3:$BL$10,2,FALSE) -> #N/A | BI19: 5. Toplumsal Hizmet ve İşbirliği Faaliyetlerinin Desteklenmesi | BJ19: 2) Kampüs içi işbirliği projelerinin desteklenmesi
A20: 14 | B20: 13802183994 | C20: ABDULLAH YÜZGEÇ | E20: ██ | F20: ██ | G20: ██ | H20: ██ | L20: ██ | M20: ██ | N20: ██ | O20: ██ | S20: ██ | T20: ██ | U20: ██ | V20: ██ | Z20: ██ | AA20: ██ | AB20: ██ | AC20: ██ | AG20: ██ | AI20: =COUNTBLANK(D20:AG20) -> 13 | AJ20: =IF(B20>10000000,AI20,0) -> 13 | AK20: =AO20-AN20 -> 0 | AM20: =MONTH(AW20) -> 6 | AN20: =COUNTA(D20:AH20) -> 30 | AO20: =IF(AM20=1,AP20,IF(AM20=2,AR20,IF(AM20=3,AP20,IF(AM20=4,AQ20,IF(AM20=5,AP20,IF(AM20=6,AQ20,IF(AM20=7,AP20,IF(AM20=8,AP20,IF(AM20=9,AQ20,IF(AM20=10,AP20,IF(AM20=11,AQ20,IF(AM20=12,AP20)))))))))))) -> 30 | AP20: 31 | AQ20: 30 | AR20: 28 | AT20: 17 | AW20: =$AW$7 -> HAZİRAN 2026 | AZ20: =VLOOKUP(AX20,$BK$3:$BL$10,2,FALSE) -> #N/A | BI20: 5. Toplumsal Hizmet ve İşbirliği Faaliyetlerinin Desteklenmesi | BJ20: 3) Sosyal inovasyon ve girişimcilik projelerinin desteklenmesi
A21: 15 | B21: 12734216152 | C21: ABDULSAMET KAYA | D21: ██ | H21: ██ | I21: ██ | J21: ██ | K21: ██ | O21: ██ | P21: ██ | Q21: ██ | R21: ██ | V21: ██ | W21: ██ | X21: ██ | Y21: ██ | AC21: ██ | AD21: ██ | AE21: ██ | AI21: =COUNTBLANK(D21:AG21) -> 14 | AJ21: =IF(B21>10000000,AI21,0) -> 14 | AK21: =AO21-AN21 -> 0 | AM21: =MONTH(AW21) -> 6 | AN21: =COUNTA(D21:AH21) -> 30 | AO21: =IF(AM21=1,AP21,IF(AM21=2,AR21,IF(AM21=3,AP21,IF(AM21=4,AQ21,IF(AM21=5,AP21,IF(AM21=6,AQ21,IF(AM21=7,AP21,IF(AM21=8,AP21,IF(AM21=9,AQ21,IF(AM21=10,AP21,IF(AM21=11,AQ21,IF(AM21=12,AP21)))))))))))) -> 30 | AP21: 31 | AQ21: 30 | AR21: 28 | AT21: 18 | AW21: =$AW$7 -> HAZİRAN 2026 | AZ21: =VLOOKUP(AX21,$BK$3:$BL$10,2,FALSE) -> #N/A | BI21: 5. Toplumsal Hizmet ve İşbirliği Faaliyetlerinin Desteklenmesi | BJ21: 4) Yaşam boyu öğrenme faaliyetlerinin desteklenmesi
A22: 16 | B22: 34354480898 | C22: ABDULSAMET ÖZDEMİR | E22: ██ | G22: ██ | I22: ██ | J22: ██ | L22: ██ | N22: ██ | P22: ██ | Q22: ██ | S22: ██ | U22: ██ | W22: ██ | X22: ██ | Y22: MG | Z22: ██ | AA22: MG | AB22: ██ | AC22: MG | AD22: ██ | AE22: ██ | AF22: MG | AG22: ██ | AI22: =COUNTBLANK(D22:AG22) -> 9 | AJ22: =IF(B22>10000000,AI22,0) -> 9 | AK22: =AO22-AN22 -> 0 | AM22: =MONTH(AW22) -> 6 | AN22: =COUNTA(D22:AH22) -> 30 | AO22: =IF(AM22=1,AP22,IF(AM22=2,AR22,IF(AM22=3,AP22,IF(AM22=4,AQ22,IF(AM22=5,AP22,IF(AM22=6,AQ22,IF(AM22=7,AP22,IF(AM22=8,AP22,IF(AM22=9,AQ22,IF(AM22=10,AP22,IF(AM22=11,AQ22,IF(AM22=12,AP22)))))))))))) -> 30 | AP22: 31 | AQ22: 30 | AR22: 28 | AT22: 19 | AW22: =$AW$7 -> HAZİRAN 2026 | AZ22: =VLOOKUP(AX22,$BK$3:$BL$10,2,FALSE) -> #N/A | BI22: 6. Öğrenci Gelişim ve Uyum Faaliyetlerinin Desteklenmesi | BJ22: 1) Akran Danışmanlığı Faaliyetlerinin Desteklenmesi
A23: 17 | B23: 12021022954 | C23: ABDULSAMET YAŞAR | G23: ██ | H23: ██ | I23: ██ | J23: ██ | L23: İ | N23: ██ | O23: ██ | P23: ██ | Q23: ██ | R23: İ | U23: ██ | V23: ██ | W23: ██ | X23: ██ | Z23: İ | AB23: ██ | AC23: ██ | AD23: ██ | AE23: ██ | AI23: =COUNTBLANK(D23:AG23) -> 11 | AJ23: =IF(B23>10000000,AI23,0) -> 11 | AK23: =AO23-AN23 -> 0 | AM23: =MONTH(AW23) -> 6 | AN23: =COUNTA(D23:AH23) -> 30 | AO23: =IF(AM23=1,AP23,IF(AM23=2,AR23,IF(AM23=3,AP23,IF(AM23=4,AQ23,IF(AM23=5,AP23,IF(AM23=6,AQ23,IF(AM23=7,AP23,IF(AM23=8,AP23,IF(AM23=9,AQ23,IF(AM23=10,AP23,IF(AM23=11,AQ23,IF(AM23=12,AP23)))))))))))) -> 30 | AP23: 31 | AQ23: 30 | AR23: 28 | AT23: 20 | AW23: =$AW$7 -> HAZİRAN 2026 | AZ23: =VLOOKUP(AX23,$BK$3:$BL$10,2,FALSE) -> #N/A | BI23: 6. Öğrenci Gelişim ve Uyum Faaliyetlerinin Desteklenmesi | BJ23: 2) Uluslararası Öğrenci Entegrasyon Faaliyetleri
A24: 18 | B24: 12179215468 | C24: ABDÜLVEKİL GÖK | G24: ██ | H24: ██ | I24: ██ | J24: ██ | N24: ██ | O24: ██ | P24: ██ | Q24: ██ | R24: MG | S24: MG | T24: MG | U24: ██ | V24: ██ | W24: ██ | X24: ██ | Y24: MG | Z24: MG | AA24: MG | AB24: ██ | AC24: ██ | AD24: ██ | AE24: ██ | AF24: MG | AG24: MG | AI24: =COUNTBLANK(D24:AG24) -> 6 | AJ24: =IF(B24>10000000,AI24,0) -> 6 | AK24: =AO24-AN24 -> 0 | AM24: =MONTH(AW24) -> 6 | AN24: =COUNTA(D24:AH24) -> 30 | AO24: =IF(AM24=1,AP24,IF(AM24=2,AR24,IF(AM24=3,AP24,IF(AM24=4,AQ24,IF(AM24=5,AP24,IF(AM24=6,AQ24,IF(AM24=7,AP24,IF(AM24=8,AP24,IF(AM24=9,AQ24,IF(AM24=10,AP24,IF(AM24=11,AQ24,IF(AM24=12,AP24)))))))))))) -> 30 | AP24: 31 | AQ24: 30 | AR24: 28 | AT24: 21 | AW24: =$AW$7 -> HAZİRAN 2026 | AZ24: =VLOOKUP(AX24,$BK$3:$BL$10,2,FALSE) -> #N/A | BI24: 6. Öğrenci Gelişim ve Uyum Faaliyetlerinin Desteklenmesi | BJ24: 3) Kariyer Gelişim Faaliyetlerinin Desteklenmesi
A25: 19 | B25: 11516080912 | C25: ABDURRAHMAN YAVUZ | G25: ██ | H25: ██ | I25: ██ | J25: ██ | N25: ██ | O25: ██ | P25: ██ | Q25: ██ | U25: ██ | V25: ██ | W25: ██ | X25: ██ | Y25: ██ | Z25: ██ | AA25: ██ | AB25: ██ | AC25: ██ | AD25: ██ | AE25: ██ | AF25: ██ | AG25: ██ | AI25: =COUNTBLANK(D25:AG25) -> 9 | AJ25: =IF(B25>10000000,AI25,0) -> 9 | AK25: =AO25-AN25 -> 0 | AM25: =MONTH(AW25) -> 6 | AN25: =COUNTA(D25:AH25) -> 30 | AO25: =IF(AM25=1,AP25,IF(AM25=2,AR25,IF(AM25=3,AP25,IF(AM25=4,AQ25,IF(AM25=5,AP25,IF(AM25=6,AQ25,IF(AM25=7,AP25,IF(AM25=8,AP25,IF(AM25=9,AQ25,IF(AM25=10,AP25,IF(AM25=11,AQ25,IF(AM25=12,AP25)))))))))))) -> 30 | AP25: 31 | AQ25: 30 | AR25: 28 | AT25: 22 | AW25: =$AW$7 -> HAZİRAN 2026 | AZ25: =VLOOKUP(AX25,$BK$3:$BL$10,2,FALSE) -> #N/A | BI25: 7. Dijital Dönüşüm ve İnovasyon Faaliyetlerinin Desteklenmesi | BJ25: 1) Dijital İçerik Geliştirme
A26: 20 | B26: 58198589036 | C26: ABDURRAHMAN EMRE COŞKUN | D26: ██ | H26: ██ | I26: ██ | J26: ██ | K26: ██ | O26: ██ | P26: ██ | Q26: ██ | R26: ██ | V26: ██ | W26: ██ | X26: ██ | Y26: ██ | AC26: ██ | AD26: ██ | AE26: ██ | AF26: ██ | AG26: MG | AI26: =COUNTBLANK(D26:AG26) -> 12 | AJ26: =IF(B26>10000000,AI26,0) -> 12 | AK26: =AO26-AN26 -> 0 | AM26: =MONTH(AW26) -> 6 | AN26: =COUNTA(D26:AH26) -> 30 | AO26: =IF(AM26=1,AP26,IF(AM26=2,AR26,IF(AM26=3,AP26,IF(AM26=4,AQ26,IF(AM26=5,AP26,IF(AM26=6,AQ26,IF(AM26=7,AP26,IF(AM26=8,AP26,IF(AM26=9,AQ26,IF(AM26=10,AP26,IF(AM26=11,AQ26,IF(AM26=12,AP26)))))))))))) -> 30 | AP26: 31 | AQ26: 30 | AR26: 28 | AT26: 23 | AW26: =$AW$7 -> HAZİRAN 2026 | AZ26: =VLOOKUP(AX26,$BK$3:$BL$10,2,FALSE) -> #N/A | BI26: 7. Dijital Dönüşüm ve İnovasyon Faaliyetlerinin Desteklenmesi | BJ26: 2) Teknoloji Destek Hizmetlerinin Desteklenmesi
A27: 21 | B27: 12964210364 | C27: ABDURRAHMAN İHSAN ERDEMİR | F27: ██ | G27: ██ | I27: ██ | J27: ██ | M27: ██ | N27: ██ | P27: ██ | Q27: ██ | T27: ██ | U27: ██ | W27: ██ | X27: ██ | Y27: İ | Z27: İ | AA27: ██ | AB27: ██ | AC27: İ | AD27: ██ | AE27: ██ | AF27: İ | AG27: İ | AI27: =COUNTBLANK(D27:AG27) -> 9 | AJ27: =IF(B27>10000000,AI27,0) -> 9 | AK27: =AO27-AN27 -> 0 | AM27: =MONTH(AW27) -> 6 | AN27: =COUNTA(D27:AH27) -> 30 | AO27: =IF(AM27=1,AP27,IF(AM27=2,AR27,IF(AM27=3,AP27,IF(AM27=4,AQ27,IF(AM27=5,AP27,IF(AM27=6,AQ27,IF(AM27=7,AP27,IF(AM27=8,AP27,IF(AM27=9,AQ27,IF(AM27=10,AP27,IF(AM27=11,AQ27,IF(AM27=12,AP27)))))))))))) -> 30 | AP27: 31 | AQ27: 30 | AR27: 28 | AT27: 24 | AW27: =$AW$7 -> HAZİRAN 2026 | AZ27: =VLOOKUP(AX27,$BK$3:$BL$10,2,FALSE) -> #N/A | BI27: 8. Girişimcilik Ekosistemi Faaliyetlerinin Desteklenmesi | BJ27: 1) Kuluçka Merkezi Operasyonları
A28: 22 | B28: 15580962310 | C28: ABDURRAHMAN KADİR ÇETİN | G28: ██ | H28: ██ | I28: ██ | J28: ██ | N28: ██ | O28: ██ | P28: ██ | Q28: ██ | U28: ██ | V28: ██ | W28: ██ | X28: ██ | AB28: ██ | AC28: ██ | AD28: ██ | AE28: ██ | AI28: =COUNTBLANK(D28:AG28) -> 14 | AJ28: =IF(B28>10000000,AI28,0) -> 14 | AK28: =AO28-AN28 -> 0 | AM28: =MONTH(AW28) -> 6 | AN28: =COUNTA(D28:AH28) -> 30 | AO28: =IF(AM28=1,AP28,IF(AM28=2,AR28,IF(AM28=3,AP28,IF(AM28=4,AQ28,IF(AM28=5,AP28,IF(AM28=6,AQ28,IF(AM28=7,AP28,IF(AM28=8,AP28,IF(AM28=9,AQ28,IF(AM28=10,AP28,IF(AM28=11,AQ28,IF(AM28=12,AP28)))))))))))) -> 30 | AP28: 31 | AQ28: 30 | AR28: 28 | AT28: 25 | AW28: =$AW$7 -> HAZİRAN 2026 | AZ28: =VLOOKUP(AX28,$BK$3:$BL$10,2,FALSE) -> #N/A | BI28: 8. Girişimcilik Ekosistemi Faaliyetlerinin Desteklenmesi | BJ28: 2) Teknoloji Transfer Ofisi Faaliyetleri
A29: 23 | B29: 10435498600 | C29: ABDÜSSAMED SARI | D29: ██ | E29: ██ | I29: ██ | J29: ██ | K29: ██ | L29: ██ | P29: ██ | Q29: ██ | R29: ██ | S29: ██ | W29: ██ | X29: ██ | Y29: ██ | Z29: ██ | AD29: ██ | AE29: ██ | AI29: =COUNTBLANK(D29:AG29) -> 14 | AJ29: =IF(B29>10000000,AI29,0) -> 14 | AK29: =AO29-AN29 -> 0 | AM29: =MONTH(AW29) -> 6 | AN29: =COUNTA(D29:AH29) -> 30 | AO29: =IF(AM29=1,AP29,IF(AM29=2,AR29,IF(AM29=3,AP29,IF(AM29=4,AQ29,IF(AM29=5,AP29,IF(AM29=6,AQ29,IF(AM29=7,AP29,IF(AM29=8,AP29,IF(AM29=9,AQ29,IF(AM29=10,AP29,IF(AM29=11,AQ29,IF(AM29=12,AP29)))))))))))) -> 30 | AP29: 31 | AQ29: 30 | AR29: 28 | AT29: 26 | AW29: =$AW$7 -> HAZİRAN 2026 | AZ29: =VLOOKUP(AX29,$BK$3:$BL$10,2,FALSE) -> #N/A
A30: 24 | B30: 10126514640 | C30: ABUZER BOYNUKARA | G30: ██ | H30: ██ | I30: ██ | J30: ██ | N30: ██ | O30: ██ | P30: ██ | Q30: ██ | U30: ██ | V30: ██ | W30: ██ | X30: ██ | Y30: İ | Z30: İ | AA30: İ | AB30: ██ | AC30: ██ | AD30: ██ | AE30: ██ | AF30: İ | AG30: İ | AI30: =COUNTBLANK(D30:AG30) -> 9 | AJ30: =IF(B30>10000000,AI30,0) -> 9 | AK30: =AO30-AN30 -> 0 | AM30: =MONTH(AW30) -> 6 | AN30: =COUNTA(D30:AH30) -> 30 | AO30: =IF(AM30=1,AP30,IF(AM30=2,AR30,IF(AM30=3,AP30,IF(AM30=4,AQ30,IF(AM30=5,AP30,IF(AM30=6,AQ30,IF(AM30=7,AP30,IF(AM30=8,AP30,IF(AM30=9,AQ30,IF(AM30=10,AP30,IF(AM30=11,AQ30,IF(AM30=12,AP30)))))))))))) -> 30 | AP30: 31 | AQ30: 30 | AR30: 28 | AT30: 27 | AW30: =$AW$7 -> HAZİRAN 2026 | AZ30: =VLOOKUP(AX30,$BK$3:$BL$10,2,FALSE) -> #N/A
A31: 25 | B31: 41851235852 | C31: ABUZER ŞAHAN | D31: ██ | E31: ██ | I31: ██ | J31: ██ | N31: ██ | O31: ██ | P31: ██ | Q31: ██ | U31: ██ | V31: ██ | W31: ██ | X31: ██ | AB31: ██ | AC31: ██ | AD31: ██ | AE31: ██ | AI31: =COUNTBLANK(D31:AG31) -> 14 | AJ31: =IF(B31>10000000,AI31,0) -> 14 | AK31: =AO31-AN31 -> 0 | AM31: =MONTH(AW31) -> 6 | AN31: =COUNTA(D31:AH31) -> 30 | AO31: =IF(AM31=1,AP31,IF(AM31=2,AR31,IF(AM31=3,AP31,IF(AM31=4,AQ31,IF(AM31=5,AP31,IF(AM31=6,AQ31,IF(AM31=7,AP31,IF(AM31=8,AP31,IF(AM31=9,AQ31,IF(AM31=10,AP31,IF(AM31=11,AQ31,IF(AM31=12,AP31)))))))))))) -> 30 | AP31: 31 | AQ31: 30 | AR31: 28 | AT31: 28 | AW31: =$AW$7 -> HAZİRAN 2026 | AZ31: =VLOOKUP(AX31,$BK$3:$BL$10,2,FALSE) -> #N/A
A32: 26 | B32: 33472284968 | C32: ADEM AKTA | G32: ██ | H32: ██ | I32: ██ | J32: ██ | N32: ██ | O32: ██ | P32: ██ | Q32: ██ | U32: ██ | V32: ██ | W32: ██ | X32: ██ | Y32: ██ | Z32: ██ | AA32: ██ | AB32: ██ | AC32: ██ | AD32: ██ | AE32: ██ | AF32: ██ | AG32: ██ | AI32: =COUNTBLANK(D32:AG32) -> 9 | AJ32: =IF(B32>10000000,AI32,0) -> 9 | AK32: =AO32-AN32 -> 0 | AL32: ▒▒ | AM32: =MONTH(AW32) -> 6 | AN32: =COUNTA(D32:AH32) -> 30 | AO32: =IF(AM32=1,AP32,IF(AM32=2,AR32,IF(AM32=3,AP32,IF(AM32=4,AQ32,IF(AM32=5,AP32,IF(AM32=6,AQ32,IF(AM32=7,AP32,IF(AM32=8,AP32,IF(AM32=9,AQ32,IF(AM32=10,AP32,IF(AM32=11,AQ32,IF(AM32=12,AP32)))))))))))) -> 30 | AP32: 31 | AQ32: 30 | AR32: 28 | AT32: 29 | AW32: =$AW$7 -> HAZİRAN 2026 | AZ32: =VLOOKUP(AX32,$BK$3:$BL$10,2,FALSE) -> #N/A
A33: 27 | B33: 11276752944 | C33: ADİL EMİRHAN AYAZ | G33: ██ | H33: ██ | I33: ██ | J33: ██ | N33: ██ | O33: ██ | P33: ██ | Q33: ██ | U33: ██ | V33: ██ | W33: ██ | X33: ██ | AB33: ██ | AC33: ██ | AD33: ██ | AE33: ██ | AI33: =COUNTBLANK(D33:AG33) -> 14 | AJ33: =IF(B33>10000000,AI33,0) -> 14 | AK33: =AO33-AN33 -> 0 | AL33: Ü | AM33: =MONTH(AW33) -> 6 | AN33: =COUNTA(D33:AH33) -> 30 | AO33: =IF(AM33=1,AP33,IF(AM33=2,AR33,IF(AM33=3,AP33,IF(AM33=4,AQ33,IF(AM33=5,AP33,IF(AM33=6,AQ33,IF(AM33=7,AP33,IF(AM33=8,AP33,IF(AM33=9,AQ33,IF(AM33=10,AP33,IF(AM33=11,AQ33,IF(AM33=12,AP33)))))))))))) -> 30 | AP33: 31 | AQ33: 30 | AR33: 28 | AT33: 30 | AW33: =$AW$7 -> HAZİRAN 2026 | AZ33: =VLOOKUP(AX33,$BK$3:$BL$10,2,FALSE) -> #N/A
A34: 28 | B34: 11438104260 | C34: AFRA DİLA HASANOĞLU | D34: ██ | G34: ██ | I34: ██ | J34: ██ | K34: ██ | N34: ██ | P34: ██ | Q34: ██ | R34: ██ | U34: ██ | W34: ██ | X34: ██ | Y34: ██ | AB34: ██ | AD34: ██ | AE34: ██ | AF34: ██ | AI34: =COUNTBLANK(D34:AG34) -> 13 | AJ34: =IF(B34>10000000,AI34,0) -> 13 | AK34: =AO34-AN34 -> 0 | AL34: S | AM34: =MONTH(AW34) -> 6 | AN34: =COUNTA(D34:AH34) -> 30 | AO34: =IF(AM34=1,AP34,IF(AM34=2,AR34,IF(AM34=3,AP34,IF(AM34=4,AQ34,IF(AM34=5,AP34,IF(AM34=6,AQ34,IF(AM34=7,AP34,IF(AM34=8,AP34,IF(AM34=9,AQ34,IF(AM34=10,AP34,IF(AM34=11,AQ34,IF(AM34=12,AP34)))))))))))) -> 30 | AP34: 31 | AQ34: 30 | AR34: 28 | AW34: =$AW$7 -> HAZİRAN 2026 | AZ34: =VLOOKUP(AX34,$BK$3:$BL$10,2,FALSE) -> #N/A
A35: 29 | B35: 10590069448 | C35: AHMET ADAR | G35: ██ | H35: ██ | I35: ██ | J35: ██ | N35: ██ | O35: ██ | P35: ██ | Q35: ██ | U35: ██ | V35: ██ | W35: ██ | X35: ██ | Y35: MG | Z35: MG | AA35: MG | AB35: ██ | AC35: ██ | AD35: ██ | AE35: ██ | AF35: MG | AG35: MG | AI35: =COUNTBLANK(D35:AG35) -> 9 | AJ35: =IF(B35>10000000,AI35,0) -> 9 | AK35: =AO35-AN35 -> 0 | AL35: M | AM35: =MONTH(AW35) -> 6 | AN35: =COUNTA(D35:AH35) -> 30 | AO35: =IF(AM35=1,AP35,IF(AM35=2,AR35,IF(AM35=3,AP35,IF(AM35=4,AQ35,IF(AM35=5,AP35,IF(AM35=6,AQ35,IF(AM35=7,AP35,IF(AM35=8,AP35,IF(AM35=9,AQ35,IF(AM35=10,AP35,IF(AM35=11,AQ35,IF(AM35=12,AP35)))))))))))) -> 30 | AP35: 31 | AQ35: 30 | AR35: 28 | AW35: =$AW$7 -> HAZİRAN 2026 | AZ35: =VLOOKUP(AX35,$BK$3:$BL$10,2,FALSE) -> #N/A
A36: 30 | B36: 55543577472 | C36: AHMET ARCA | F36: ██ | G36: ██ | I36: ██ | J36: ██ | M36: ██ | N36: ██ | P36: ██ | Q36: ██ | T36: ██ | U36: ██ | W36: ██ | X36: ██ | AA36: ██ | AB36: ██ | AD36: ██ | AE36: ██ | AI36: =COUNTBLANK(D36:AG36) -> 14 | AJ36: =IF(B36>10000000,AI36,0) -> 14 | AK36: =AO36-AN36 -> 0 | AL36: İ | AM36: =MONTH(AW36) -> 6 | AN36: =COUNTA(D36:AH36) -> 30 | AO36: =IF(AM36=1,AP36,IF(AM36=2,AR36,IF(AM36=3,AP36,IF(AM36=4,AQ36,IF(AM36=5,AP36,IF(AM36=6,AQ36,IF(AM36=7,AP36,IF(AM36=8,AP36,IF(AM36=9,AQ36,IF(AM36=10,AP36,IF(AM36=11,AQ36,IF(AM36=12,AP36)))))))))))) -> 30 | AP36: 31 | AQ36: 30 | AR36: 28 | AW36: =$AW$7 -> HAZİRAN 2026 | AZ36: =VLOOKUP(AX36,$BK$3:$BL$10,2,FALSE) -> #N/A
A37: 31 | B37: 58825297792 | C37: AHMET ATASEVEN | E37: ██ | H37: ██ | I37: ██ | J37: ██ | L37: ██ | O37: ██ | P37: ██ | Q37: ██ | S37: ██ | V37: ██ | W37: ██ | X37: ██ | Z37: ██ | AC37: ██ | AD37: ██ | AE37: ██ | AI37: =COUNTBLANK(D37:AG37) -> 14 | AJ37: =IF(B37>10000000,AI37,0) -> 14 | AK37: =AO37-AN37 -> 0 | AL37: D | AM37: =MONTH(AW37) -> 6 | AN37: =COUNTA(D37:AH37) -> 30 | AO37: =IF(AM37=1,AP37,IF(AM37=2,AR37,IF(AM37=3,AP37,IF(AM37=4,AQ37,IF(AM37=5,AP37,IF(AM37=6,AQ37,IF(AM37=7,AP37,IF(AM37=8,AP37,IF(AM37=9,AQ37,IF(AM37=10,AP37,IF(AM37=11,AQ37,IF(AM37=12,AP37)))))))))))) -> 30 | AP37: 31 | AQ37: 30 | AR37: 28 | AW37: =$AW$7 -> HAZİRAN 2026 | AZ37: =VLOOKUP(AX37,$BK$3:$BL$10,2,FALSE) -> #N/A
A38: 32 | B38: 30662502284 | C38: AHMET BAYKUŞ | E38: ██ | G38: ██ | I38: ██ | J38: ██ | L38: ██ | N38: ██ | P38: ██ | Q38: ██ | S38: ██ | U38: ██ | W38: ██ | X38: ██ | Y38: İ | Z38: ██ | AA38: İ | AB38: ██ | AC38: İ | AD38: ██ | AE38: ██ | AF38: İ | AG38: ██ | AI38: =COUNTBLANK(D38:AG38) -> 9 | AJ38: =IF(B38>10000000,AI38,0) -> 9 | AK38: =AO38-AN38 -> 0 | AM38: =MONTH(AW38) -> 6 | AN38: =COUNTA(D38:AH38) -> 30 | AO38: =IF(AM38=1,AP38,IF(AM38=2,AR38,IF(AM38=3,AP38,IF(AM38=4,AQ38,IF(AM38=5,AP38,IF(AM38=6,AQ38,IF(AM38=7,AP38,IF(AM38=8,AP38,IF(AM38=9,AQ38,IF(AM38=10,AP38,IF(AM38=11,AQ38,IF(AM38=12,AP38)))))))))))) -> 30 | AP38: 31 | AQ38: 30 | AR38: 28 | AW38: =$AW$7 -> HAZİRAN 2026 | AZ38: =VLOOKUP(AX38,$BK$3:$BL$10,2,FALSE) -> #N/A
A39: 33 | B39: 45049880008 | C39: AHMET BIRASOĞLU | G39: ██ | H39: ██ | I39: ██ | J39: ██ | N39: ██ | O39: ██ | P39: ██ | Q39: ██ | R39: ██ | S39: ██ | T39: ██ | U39: ██ | V39: ██ | W39: ██ | X39: ██ | Y39: ██ | Z39: ██ | AA39: ██ | AB39: ██ | AC39: ██ | AD39: ██ | AE39: ██ | AF39: ██ | AG39: ██ | AI39: =COUNTBLANK(D39:AG39) -> 6 | AJ39: =IF(B39>10000000,AI39,0) -> 6 | AK39: =AO39-AN39 -> 0 | AM39: =MONTH(AW39) -> 6 | AN39: =COUNTA(D39:AH39) -> 30 | AO39: =IF(AM39=1,AP39,IF(AM39=2,AR39,IF(AM39=3,AP39,IF(AM39=4,AQ39,IF(AM39=5,AP39,IF(AM39=6,AQ39,IF(AM39=7,AP39,IF(AM39=8,AP39,IF(AM39=9,AQ39,IF(AM39=10,AP39,IF(AM39=11,AQ39,IF(AM39=12,AP39)))))))))))) -> 30 | AP39: 31 | AQ39: 30 | AR39: 28 | AW39: =$AW$7 -> HAZİRAN 2026 | AZ39: =VLOOKUP(AX39,$BK$3:$BL$10,2,FALSE) -> #N/A
A40: 34 | B40: 57787292906 | C40: AHMET ÇAĞLAYAN | E40: ██ | G40: ██ | I40: ██ | J40: ██ | L40: ██ | N40: ██ | P40: ██ | Q40: ██ | S40: ██ | U40: ██ | W40: ██ | X40: ██ | Z40: ██ | AB40: ██ | AD40: ██ | AE40: ██ | AG40: ██ | AI40: =COUNTBLANK(D40:AG40) -> 13 | AJ40: =IF(B40>10000000,AI40,0) -> 13 | AK40: =AO40-AN40 -> 0 | AM40: =MONTH(AW40) -> 6 | AN40: =COUNTA(D40:AH40) -> 30 | AO40: =IF(AM40=1,AP40,IF(AM40=2,AR40,IF(AM40=3,AP40,IF(AM40=4,AQ40,IF(AM40=5,AP40,IF(AM40=6,AQ40,IF(AM40=7,AP40,IF(AM40=8,AP40,IF(AM40=9,AQ40,IF(AM40=10,AP40,IF(AM40=11,AQ40,IF(AM40=12,AP40)))))))))))) -> 30 | AP40: 31 | AQ40: 30 | AR40: 28 | AW40: =$AW$7 -> HAZİRAN 2026 | AZ40: =VLOOKUP(AX40,$BK$3:$BL$10,2,FALSE) -> #N/A
...

Sheet 2-Bordro
B1: Sıra No | C1: İş Yeri Ünvanı | D1: ='!!! VERİLER !!!'!C4 -> GAZİANTEP REKTÖRLÜĞÜ | H1: Hesap No : | N1: ='!!! VERİLER !!!'!C8 -> TR310001200133800004000406 | V1: Sıra No
C2: SGK İşyeri Sicil Numarası | D2: ='!!! VERİLER !!!'!C7 -> 385400101122832602709-30/000 | G2: Çalışan Sayısı | H2: =COUNTIF(F5:F2004,">=1") -> 1482 | M2: Ait Olduğu Ay : | O2: ='1-Devamsızlık Formu (Ek-4)'!P1 -> HAZİRAN | P2: ='1-Devamsızlık Formu (Ek-4)'!C1 -> 2026
C3: ADI SOYADI | D3: T.C.KİMLİK NUMARASI | E3: CEP HARÇLIĞI TUTARI | F3: ÇALIŞTIĞI GÜN SAYISI | G3: AYLIK | H3: Kısa Vadeli Sigorta Kolları Primi | I3: TOPLAM SGK PRİM TUTARI | J3: Gelir Vergisi | K3: Gelir Vergisi | L3: Ödenecek | M3: Asgari Geçim İndirimi | N3: Genel Sağlık Sigortası Primi | O3: SGK PRİMİ TOPLAM | P3: TOPLAM MALİYET | Q3: İCRA | R3: NET | S3: Risk Primi | T3: İşsizlik | U3: TOPLAM TAHAKKUK
G4: NET ÜCRET | H4: 0.01 | I4: 0.055 | J4: Matrahı | K4: 0.15 | L4: Gelir vergisi | N4: 0.045 | O4: 0.055 | P4: MAAŞ+SİGORTA | Q4: KESİNTİSİ | R4: ELE GEÇEN | S4: 0.0225 | T4: 0.02
B5: 1 | C5: ='!!!KATILIMCI LİSTESİ!!!'!B2 -> ABDÜLAZİZ BÜYÜKDEMİR | D5: ='!!!KATILIMCI LİSTESİ!!!'!C2 -> 11231264864 | E5: ='!!! VERİLER !!!'!C1 -> 1375 | F5: ='1-Devamsızlık Formu (Ek-4)'!AJ7 -> 14 | G5: =IF(AND('1-Devamsızlık Formu (Ek-4)'!D7="",F5>0,'1-Devamsızlık Formu (Ek-4)'!AW7="KASIM 2024"),(E5*(F5-1)+(666.75)),E5*F5) -> 19250 | H5: =G5*0.01 -> 192.5 | I5: =G5*0.045 -> 866.25 | J5: =IF(G5>20002.5,(G5-H5-I5)-(17002.12),0) -> 0 | K5: =J5*0.15 -> 0 | L5: =ROUND(K5-M5,2) -> #REF! | M5: =IF(K5-'!!!KATILIMCI LİSTESİ!!!'!#REF!>0,'!!!KATILIMCI LİSTESİ!!!'!#REF!,K5) -> #REF! | N5: =G5*0.045 -> 866.25 | O5: =G5*0.055 -> 1058.75 | P5: =G5+O5 -> 20308.75 | Q5: ='5-Banka Listesi'!G6 -> 0 | R5: =G5-Q5 -> 19250 | S5: =ROUND(G5*0.0225,3) -> 433.125 | T5: =ROUND(G5*0.02,3) -> 385 | U5: =ROUND(Q5+R5+S5+T5,3) -> 20068.125 | V5: 1
B6: 2 | C6: ='!!!KATILIMCI LİSTESİ!!!'!B3 -> ABDULBAKİ DALGIN | D6: ='!!!KATILIMCI LİSTESİ!!!'!C3 -> 51664708658 | E6: ='!!! VERİLER !!!'!C1 -> 1375 | F6: ='1-Devamsızlık Formu (Ek-4)'!AJ8 -> 14 | G6: =IF(AND('1-Devamsızlık Formu (Ek-4)'!D8="",F6>0,'1-Devamsızlık Formu (Ek-4)'!AW8="KASIM 2024"),(E6*(F6-1)+(666.75)),E6*F6) -> 19250 | H6: =G6*0.01 -> 192.5 | I6: =G6*0.01 -> 192.5 | J6: =IF(G6>20002.5,(G6-H6-I6)-(17002.12),0) -> 0 | K6: =J6*0.15 -> 0 | L6: =ROUND(K6-M6,2) -> #REF! | M6: =IF(K6-'!!!KATILIMCI LİSTESİ!!!'!#REF!>0,'!!!KATILIMCI LİSTESİ!!!'!#REF!,K6) -> #REF! | N6: =G6*0.045 -> 866.25 | O6: =G6*0.055 -> 1058.75 | P6: =G6+O6 -> 20308.75 | Q6: ='5-Banka Listesi'!G7 -> 0 | R6: =G6-Q6 -> 19250 | S6: =ROUND(G6*0.0225,3) -> 433.125 | T6: =ROUND(G6*0.02,3) -> 385 | U6: =ROUND(Q6+R6+S6+T6,3) -> 20068.125 | V6: 2
B7: 3 | C7: ='!!!KATILIMCI LİSTESİ!!!'!B4 -> ABDULBASİT YİLMAZ | D7: ='!!!KATILIMCI LİSTESİ!!!'!C4 -> 12980258364 | E7: ='!!! VERİLER !!!'!C1 -> 1375 | F7: ='1-Devamsızlık Formu (Ek-4)'!AJ9 -> 11 | G7: =IF(AND('1-Devamsızlık Formu (Ek-4)'!D9="",F7>0,'1-Devamsızlık Formu (Ek-4)'!AW9="KASIM 2024"),(E7*(F7-1)+(666.75)),E7*F7) -> 15125 | H7: =G7*0.01 -> 151.25 | I7: =G7*0.01 -> 151.25 | J7: =IF(G7>20002.5,(G7-H7-I7)-(17002.12),0) -> 0 | K7: =J7*0.15 -> 0 | L7: =ROUND(K7-M7,2) -> #REF! | M7: =IF(K7-'!!!KATILIMCI LİSTESİ!!!'!#REF!>0,'!!!KATILIMCI LİSTESİ!!!'!#REF!,K7) -> #REF! | N7: =G7*0.045 -> 680.625 | O7: =G7*0.055 -> 831.875 | P7: =G7+O7 -> 15956.875 | Q7: ='5-Banka Listesi'!G8 -> 0 | R7: =G7-Q7 -> 15125 | S7: =ROUND(G7*0.0225,3) -> 340.313 | T7: =ROUND(G7*0.02,3) -> 302.5 | U7: =ROUND(Q7+R7+S7+T7,3) -> 15767.813 | V7: 3
B8: 4 | C8: ='!!!KATILIMCI LİSTESİ!!!'!B5 -> ABDULKADİR AKÇAKOCA | D8: ='!!!KATILIMCI LİSTESİ!!!'!C5 -> 10244285118 | E8: ='!!! VERİLER !!!'!C1 -> 1375 | F8: ='1-Devamsızlık Formu (Ek-4)'!AJ10 -> 14 | G8: =IF(AND('1-Devamsızlık Formu (Ek-4)'!D10="",F8>0,'1-Devamsızlık Formu (Ek-4)'!AW10="KASIM 2024"),(E8*(F8-1)+(666.75)),E8*F8) -> 19250 | H8: =G8*0.01 -> 192.5 | I8: =G8*0.01 -> 192.5 | J8: =IF(G8>20002.5,(G8-H8-I8)-(17002.12),0) -> 0 | K8: =J8*0.15 -> 0 | L8: =ROUND(K8-M8,2) -> #REF! | M8: =IF(K8-'!!!KATILIMCI LİSTESİ!!!'!#REF!>0,'!!!KATILIMCI LİSTESİ!!!'!#REF!,K8) -> #REF! | N8: =G8*0.045 -> 866.25 | O8: =G8*0.055 -> 1058.75 | P8: =G8+O8 -> 20308.75 | Q8: ='5-Banka Listesi'!G9 -> 0 | R8: =G8-Q8 -> 19250 | S8: =ROUND(G8*0.0225,3) -> 433.125 | T8: =ROUND(G8*0.02,3) -> 385 | U8: =ROUND(Q8+R8+S8+T8,3) -> 20068.125 | V8: 4
B9: 5 | C9: ='!!!KATILIMCI LİSTESİ!!!'!B6 -> ABDULKADİR ALPASLAN | D9: ='!!!KATILIMCI LİSTESİ!!!'!C6 -> 47248051944 | E9: ='!!! VERİLER !!!'!C1 -> 1375 | F9: ='1-Devamsızlık Formu (Ek-4)'!AJ11 -> 14 | G9: =IF(AND('1-Devamsızlık Formu (Ek-4)'!D11="",F9>0,'1-Devamsızlık Formu (Ek-4)'!AW11="KASIM 2024"),(E9*(F9-1)+(666.75)),E9*F9) -> 19250 | H9: =G9*0.01 -> 192.5 | I9: =G9*0.01 -> 192.5 | J9: =IF(G9>20002.5,(G9-H9-I9)-(17002.12),0) -> 0 | K9: =J9*0.15 -> 0 | L9: =ROUND(K9-M9,2) -> #REF! | M9: =IF(K9-'!!!KATILIMCI LİSTESİ!!!'!#REF!>0,'!!!KATILIMCI LİSTESİ!!!'!#REF!,K9) -> #REF! | N9: =G9*0.045 -> 866.25 | O9: =G9*0.055 -> 1058.75 | P9: =G9+O9 -> 20308.75 | Q9: ='5-Banka Listesi'!G10 -> 0 | R9: =G9-Q9 -> 19250 | S9: =ROUND(G9*0.0225,3) -> 433.125 | T9: =ROUND(G9*0.02,3) -> 385 | U9: =ROUND(Q9+R9+S9+T9,3) -> 20068.125 | V9: 5
B10: 6 | C10: ='!!!KATILIMCI LİSTESİ!!!'!B7 -> ABDULKADİR EKİNCİ | D10: ='!!!KATILIMCI LİSTESİ!!!'!C7 -> 30554505850 | E10: ='!!! VERİLER !!!'!C1 -> 1375 | F10: ='1-Devamsızlık Formu (Ek-4)'!AJ12 -> 14 | G10: =IF(AND('1-Devamsızlık Formu (Ek-4)'!D12="",F10>0,'1-Devamsızlık Formu (Ek-4)'!AW12="KASIM 2024"),(E10*(F10-1)+(666.75)),E10*F10) -> 19250 | H10: =G10*0.01 -> 192.5 | I10: =G10*0.01 -> 192.5 | J10: =IF(G10>20002.5,(G10-H10-I10)-(17002.12),0) -> 0 | K10: =J10*0.15 -> 0 | L10: =ROUND(K10-M10,2) -> #REF! | M10: =IF(K10-'!!!KATILIMCI LİSTESİ!!!'!#REF!>0,'!!!KATILIMCI LİSTESİ!!!'!#REF!,K10) -> #REF! | N10: =G10*0.045 -> 866.25 | O10: =G10*0.055 -> 1058.75 | P10: =G10+O10 -> 20308.75 | Q10: ='5-Banka Listesi'!G11 -> 0 | R10: =G10-Q10 -> 19250 | S10: =ROUND(G10*0.0225,3) -> 433.125 | T10: =ROUND(G10*0.02,3) -> 385 | U10: =ROUND(Q10+R10+S10+T10,3) -> 20068.125 | V10: 6
B11: 7 | C11: ='!!!KATILIMCI LİSTESİ!!!'!B8 -> ABDULKADİR TAŞPINAR | D11: ='!!!KATILIMCI LİSTESİ!!!'!C8 -> 11576369514 | E11: ='!!! VERİLER !!!'!C1 -> 1375 | F11: ='1-Devamsızlık Formu (Ek-4)'!AJ13 -> 6 | G11: =IF(AND('1-Devamsızlık Formu (Ek-4)'!D13="",F11>0,'1-Devamsızlık Formu (Ek-4)'!AW13="KASIM 2024"),(E11*(F11-1)+(666.75)),E11*F11) -> 8250 | H11: =G11*0.01 -> 82.5 | I11: =G11*0.01 -> 82.5 | J11: =IF(G11>20002.5,(G11-H11-I11)-(17002.12),0) -> 0 | K11: =J11*0.15 -> 0 | L11: =ROUND(K11-M11,2) -> #REF! | M11: =IF(K11-'!!!KATILIMCI LİSTESİ!!!'!#REF!>0,'!!!KATILIMCI LİSTESİ!!!'!#REF!,K11) -> #REF! | N11: =G11*0.045 -> 371.25 | O11: =G11*0.055 -> 453.75 | P11: =G11+O11 -> 8703.75 | Q11: ='5-Banka Listesi'!G12 -> 0 | R11: =G11-Q11 -> 8250 | S11: =ROUND(G11*0.0225,3) -> 185.625 | T11: =ROUND(G11*0.02,3) -> 165 | U11: =ROUND(Q11+R11+S11+T11,3) -> 8600.625 | V11: 7
B12: 8 | C12: ='!!!KATILIMCI LİSTESİ!!!'!B9 -> ABDULKADİR ÜSTÜNER | D12: ='!!!KATILIMCI LİSTESİ!!!'!C9 -> 32120360108 | E12: ='!!! VERİLER !!!'!C1 -> 1375 | F12: ='1-Devamsızlık Formu (Ek-4)'!AJ14 -> 9 | G12: =IF(AND('1-Devamsızlık Formu (Ek-4)'!D14="",F12>0,'1-Devamsızlık Formu (Ek-4)'!AW14="KASIM 2024"),(E12*(F12-1)+(666.75)),E12*F12) -> 12375 | H12: =G12*0.01 -> 123.75 | I12: =G12*0.01 -> 123.75 | J12: =IF(G12>20002.5,(G12-H12-I12)-(17002.12),0) -> 0 | K12: =J12*0.15 -> 0 | L12: =ROUND(K12-M12,2) -> #REF! | M12: =IF(K12-'!!!KATILIMCI LİSTESİ!!!'!#REF!>0,'!!!KATILIMCI LİSTESİ!!!'!#REF!,K12) -> #REF! | N12: =G12*0.045 -> 556.875 | O12: =G12*0.055 -> 680.625 | P12: =G12+O12 -> 13055.625 | Q12: ='5-Banka Listesi'!G13 -> 0 | R12: =G12-Q12 -> 12375 | S12: =ROUND(G12*0.0225,3) -> 278.438 | T12: =ROUND(G12*0.02,3) -> 247.5 | U12: =ROUND(Q12+R12+S12+T12,3) -> 12900.938 | V12: 8
B13: 9 | C13: ='!!!KATILIMCI LİSTESİ!!!'!B10 -> ABDÜLKADİR DÜK | D13: ='!!!KATILIMCI LİSTESİ!!!'!C10 -> 46378087250 | E13: ='!!! VERİLER !!!'!C1 -> 1375 | F13: ='1-Devamsızlık Formu (Ek-4)'!AJ15 -> 14 | G13: =IF(AND('1-Devamsızlık Formu (Ek-4)'!D15="",F13>0,'1-Devamsızlık Formu (Ek-4)'!AW15="KASIM 2024"),(E13*(F13-1)+(666.75)),E13*F13) -> 19250 | H13: =G13*0.01 -> 192.5 | I13: =G13*0.01 -> 192.5 | J13: =IF(G13>20002.5,(G13-H13-I13)-(17002.12),0) -> 0 | K13: =J13*0.15 -> 0 | L13: =ROUND(K13-M13,2) -> #REF! | M13: =IF(K13-'!!!KATILIMCI LİSTESİ!!!'!#REF!>0,'!!!KATILIMCI LİSTESİ!!!'!#REF!,K13) -> #REF! | N13: =G13*0.045 -> 866.25 | O13: =G13*0.055 -> 1058.75 | P13: =G13+O13 -> 20308.75 | Q13: ='5-Banka Listesi'!G14 -> 0 | R13: =G13-Q13 -> 19250 | S13: =ROUND(G13*0.0225,3) -> 433.125 | T13: =ROUND(G13*0.02,3) -> 385 | U13: =ROUND(Q13+R13+S13+T13,3) -> 20068.125 | V13: 9
B14: 10 | C14: ='!!!KATILIMCI LİSTESİ!!!'!B11 -> ABDULLAH BİNGÖL | D14: ='!!!KATILIMCI LİSTESİ!!!'!C11 -> 36059043460 | E14: ='!!! VERİLER !!!'!C1 -> 1375 | F14: ='1-Devamsızlık Formu (Ek-4)'!AJ16 -> 14 | G14: =IF(AND('1-Devamsızlık Formu (Ek-4)'!D16="",F14>0,'1-Devamsızlık Formu (Ek-4)'!AW16="KASIM 2024"),(E14*(F14-1)+(666.75)),E14*F14) -> 19250 | H14: =G14*0.01 -> 192.5 | I14: =G14*0.01 -> 192.5 | J14: =IF(G14>20002.5,(G14-H14-I14)-(17002.12),0) -> 0 | K14: =J14*0.15 -> 0 | L14: =ROUND(K14-M14,2) -> #REF! | M14: =IF(K14-'!!!KATILIMCI LİSTESİ!!!'!#REF!>0,'!!!KATILIMCI LİSTESİ!!!'!#REF!,K14) -> #REF! | N14: =G14*0.045 -> 866.25 | O14: =G14*0.055 -> 1058.75 | P14: =G14+O14 -> 20308.75 | Q14: ='5-Banka Listesi'!G15 -> 0 | R14: =G14-Q14 -> 19250 | S14: =ROUND(G14*0.0225,3) -> 433.125 | T14: =ROUND(G14*0.02,3) -> 385 | U14: =ROUND(Q14+R14+S14+T14,3) -> 20068.125 | V14: 10
B15: 11 | C15: ='!!!KATILIMCI LİSTESİ!!!'!B12 -> ABDULLAH ÇALIŞKAN | D15: ='!!!KATILIMCI LİSTESİ!!!'!C12 -> 17987044460 | E15: ='!!! VERİLER !!!'!C1 -> 1375 | F15: ='1-Devamsızlık Formu (Ek-4)'!AJ17 -> 12 | G15: =IF(AND('1-Devamsızlık Formu (Ek-4)'!D17="",F15>0,'1-Devamsızlık Formu (Ek-4)'!AW17="KASIM 2024"),(E15*(F15-1)+(666.75)),E15*F15) -> 16500 | H15: =G15*0.01 -> 165 | I15: =G15*0.01 -> 165 | J15: =IF(G15>20002.5,(G15-H15-I15)-(17002.12),0) -> 0 | K15: =J15*0.15 -> 0 | L15: =ROUND(K15-M15,2) -> #REF! | M15: =IF(K15-'!!!KATILIMCI LİSTESİ!!!'!#REF!>0,'!!!KATILIMCI LİSTESİ!!!'!#REF!,K15) -> #REF! | N15: =G15*0.045 -> 742.5 | O15: =G15*0.055 -> 907.5 | P15: =G15+O15 -> 17407.5 | Q15: ='5-Banka Listesi'!G16 -> 0 | R15: =G15-Q15 -> 16500 | S15: =ROUND(G15*0.0225,3) -> 371.25 | T15: =ROUND(G15*0.02,3) -> 330 | U15: =ROUND(Q15+R15+S15+T15,3) -> 17201.25 | V15: 11
B16: 12 | C16: ='!!!KATILIMCI LİSTESİ!!!'!B13 -> ABDULLAH İŞ | D16: ='!!!KATILIMCI LİSTESİ!!!'!C13 -> 47635631308 | E16: ='!!! VERİLER !!!'!C1 -> 1375 | F16: ='1-Devamsızlık Formu (Ek-4)'!AJ18 -> 6 | G16: =IF(AND('1-Devamsızlık Formu (Ek-4)'!D18="",F16>0,'1-Devamsızlık Formu (Ek-4)'!AW18="KASIM 2024"),(E16*(F16-1)+(666.75)),E16*F16) -> 8250 | H16: =G16*0.01 -> 82.5 | I16: =G16*0.01 -> 82.5 | J16: =IF(G16>20002.5,(G16-H16-I16)-(17002.12),0) -> 0 | K16: =J16*0.15 -> 0 | L16: =ROUND(K16-M16,2) -> #REF! | M16: =IF(K16-'!!!KATILIMCI LİSTESİ!!!'!#REF!>0,'!!!KATILIMCI LİSTESİ!!!'!#REF!,K16) -> #REF! | N16: =G16*0.045 -> 371.25 | O16: =G16*0.055 -> 453.75 | P16: =G16+O16 -> 8703.75 | Q16: ='5-Banka Listesi'!G17 -> 0 | R16: =G16-Q16 -> 8250 | S16: =ROUND(G16*0.0225,3) -> 185.625 | T16: =ROUND(G16*0.02,3) -> 165 | U16: =ROUND(Q16+R16+S16+T16,3) -> 8600.625 | V16: 12
B17: 13 | C17: ='!!!KATILIMCI LİSTESİ!!!'!B14 -> ABDULLAH ULUN | D17: ='!!!KATILIMCI LİSTESİ!!!'!C14 -> 10850337096 | E17: ='!!! VERİLER !!!'!C1 -> 1375 | F17: ='1-Devamsızlık Formu (Ek-4)'!AJ19 -> 12 | G17: =IF(AND('1-Devamsızlık Formu (Ek-4)'!D19="",F17>0,'1-Devamsızlık Formu (Ek-4)'!AW19="KASIM 2024"),(E17*(F17-1)+(666.75)),E17*F17) -> 16500 | H17: =G17*0.01 -> 165 | I17: =G17*0.01 -> 165 | J17: =IF(G17>20002.5,(G17-H17-I17)-(17002.12),0) -> 0 | K17: =J17*0.15 -> 0 | L17: =ROUND(K17-M17,2) -> #REF! | M17: =IF(K17-'!!!KATILIMCI LİSTESİ!!!'!#REF!>0,'!!!KATILIMCI LİSTESİ!!!'!#REF!,K17) -> #REF! | N17: =G17*0.045 -> 742.5 | O17: =G17*0.055 -> 907.5 | P17: =G17+O17 -> 17407.5 | Q17: ='5-Banka Listesi'!G18 -> 0 | R17: =G17-Q17 -> 16500 | S17: =ROUND(G17*0.0225,3) -> 371.25 | T17: =ROUND(G17*0.02,3) -> 330 | U17: =ROUND(Q17+R17+S17+T17,3) -> 17201.25 | V17: 13
B18: 14 | C18: ='!!!KATILIMCI LİSTESİ!!!'!B15 -> ABDULLAH YÜZGEÇ | D18: ='!!!KATILIMCI LİSTESİ!!!'!C15 -> 13802183994 | E18: ='!!! VERİLER !!!'!C1 -> 1375 | F18: ='1-Devamsızlık Formu (Ek-4)'!AJ20 -> 13 | G18: =IF(AND('1-Devamsızlık Formu (Ek-4)'!D20="",F18>0,'1-Devamsızlık Formu (Ek-4)'!AW20="KASIM 2024"),(E18*(F18-1)+(666.75)),E18*F18) -> 17875 | H18: =G18*0.01 -> 178.75 | I18: =G18*0.01 -> 178.75 | J18: =IF(G18>20002.5,(G18-H18-I18)-(17002.12),0) -> 0 | K18: =J18*0.15 -> 0 | L18: =ROUND(K18-M18,2) -> #REF! | M18: =IF(K18-'!!!KATILIMCI LİSTESİ!!!'!#REF!>0,'!!!KATILIMCI LİSTESİ!!!'!#REF!,K18) -> #REF! | N18: =G18*0.045 -> 804.375 | O18: =G18*0.055 -> 983.125 | P18: =G18+O18 -> 18858.125 | Q18: ='5-Banka Listesi'!G19 -> 0 | R18: =G18-Q18 -> 17875 | S18: =ROUND(G18*0.0225,3) -> 402.188 | T18: =ROUND(G18*0.02,3) -> 357.5 | U18: =ROUND(Q18+R18+S18+T18,3) -> 18634.688 | V18: 14
B19: 15 | C19: ='!!!KATILIMCI LİSTESİ!!!'!B16 -> ABDULSAMET KAYA | D19: ='!!!KATILIMCI LİSTESİ!!!'!C16 -> 12734216152 | E19: ='!!! VERİLER !!!'!C1 -> 1375 | F19: ='1-Devamsızlık Formu (Ek-4)'!AJ21 -> 14 | G19: =IF(AND('1-Devamsızlık Formu (Ek-4)'!D21="",F19>0,'1-Devamsızlık Formu (Ek-4)'!AW21="KASIM 2024"),(E19*(F19-1)+(666.75)),E19*F19) -> 19250 | H19: =G19*0.01 -> 192.5 | I19: =G19*0.01 -> 192.5 | J19: =IF(G19>20002.5,(G19-H19-I19)-(17002.12),0) -> 0 | K19: =J19*0.15 -> 0 | L19: =ROUND(K19-M19,2) -> #REF! | M19: =IF(K19-'!!!KATILIMCI LİSTESİ!!!'!#REF!>0,'!!!KATILIMCI LİSTESİ!!!'!#REF!,K19) -> #REF! | N19: =G19*0.045 -> 866.25 | O19: =G19*0.055 -> 1058.75 | P19: =G19+O19 -> 20308.75 | Q19: ='5-Banka Listesi'!G20 -> 0 | R19: =G19-Q19 -> 19250 | S19: =ROUND(G19*0.0225,3) -> 433.125 | T19: =ROUND(G19*0.02,3) -> 385 | U19: =ROUND(Q19+R19+S19+T19,3) -> 20068.125 | V19: 15
B20: 16 | C20: ='!!!KATILIMCI LİSTESİ!!!'!B17 -> ABDULSAMET ÖZDEMİR | D20: ='!!!KATILIMCI LİSTESİ!!!'!C17 -> 34354480898 | E20: ='!!! VERİLER !!!'!C1 -> 1375 | F20: ='1-Devamsızlık Formu (Ek-4)'!AJ22 -> 9 | G20: =IF(AND('1-Devamsızlık Formu (Ek-4)'!D22="",F20>0,'1-Devamsızlık Formu (Ek-4)'!AW22="KASIM 2024"),(E20*(F20-1)+(666.75)),E20*F20) -> 12375 | H20: =G20*0.01 -> 123.75 | I20: =G20*0.01 -> 123.75 | J20: =IF(G20>20002.5,(G20-H20-I20)-(17002.12),0) -> 0 | K20: =J20*0.15 -> 0 | L20: =ROUND(K20-M20,2) -> #REF! | M20: =IF(K20-'!!!KATILIMCI LİSTESİ!!!'!#REF!>0,'!!!KATILIMCI LİSTESİ!!!'!#REF!,K20) -> #REF! | N20: =G20*0.045 -> 556.875 | O20: =G20*0.055 -> 680.625 | P20: =G20+O20 -> 13055.625 | Q20: ='5-Banka Listesi'!G21 -> 0 | R20: =G20-Q20 -> 12375 | S20: =ROUND(G20*0.0225,3) -> 278.438 | T20: =ROUND(G20*0.02,3) -> 247.5 | U20: =ROUND(Q20+R20+S20+T20,3) -> 12900.938 | V20: 16
B21: 17 | C21: ='!!!KATILIMCI LİSTESİ!!!'!B18 -> ABDULSAMET YAŞAR | D21: ='!!!KATILIMCI LİSTESİ!!!'!C18 -> 12021022954 | E21: ='!!! VERİLER !!!'!C1 -> 1375 | F21: ='1-Devamsızlık Formu (Ek-4)'!AJ23 -> 11 | G21: =IF(AND('1-Devamsızlık Formu (Ek-4)'!D23="",F21>0,'1-Devamsızlık Formu (Ek-4)'!AW23="KASIM 2024"),(E21*(F21-1)+(666.75)),E21*F21) -> 15125 | H21: =G21*0.01 -> 151.25 | I21: =G21*0.01 -> 151.25 | J21: =IF(G21>20002.5,(G21-H21-I21)-(17002.12),0) -> 0 | K21: =J21*0.15 -> 0 | L21: =ROUND(K21-M21,2) -> #REF! | M21: =IF(K21-'!!!KATILIMCI LİSTESİ!!!'!#REF!>0,'!!!KATILIMCI LİSTESİ!!!'!#REF!,K21) -> #REF! | N21: =G21*0.045 -> 680.625 | O21: =G21*0.055 -> 831.875 | P21: =G21+O21 -> 15956.875 | Q21: ='5-Banka Listesi'!G22 -> 0 | R21: =G21-Q21 -> 15125 | S21: =ROUND(G21*0.0225,3) -> 340.313 | T21: =ROUND(G21*0.02,3) -> 302.5 | U21: =ROUND(Q21+R21+S21+T21,3) -> 15767.813 | V21: 17
B22: 18 | C22: ='!!!KATILIMCI LİSTESİ!!!'!B19 -> ABDÜLVEKİL GÖK | D22: ='!!!KATILIMCI LİSTESİ!!!'!C19 -> 12179215468 | E22: ='!!! VERİLER !!!'!C1 -> 1375 | F22: ='1-Devamsızlık Formu (Ek-4)'!AJ24 -> 6 | G22: =IF(AND('1-Devamsızlık Formu (Ek-4)'!D24="",F22>0,'1-Devamsızlık Formu (Ek-4)'!AW24="KASIM 2024"),(E22*(F22-1)+(666.75)),E22*F22) -> 8250 | H22: =G22*0.01 -> 82.5 | I22: =G22*0.01 -> 82.5 | J22: =IF(G22>20002.5,(G22-H22-I22)-(17002.12),0) -> 0 | K22: =J22*0.15 -> 0 | L22: =ROUND(K22-M22,2) -> #REF! | M22: =IF(K22-'!!!KATILIMCI LİSTESİ!!!'!#REF!>0,'!!!KATILIMCI LİSTESİ!!!'!#REF!,K22) -> #REF! | N22: =G22*0.045 -> 371.25 | O22: =G22*0.055 -> 453.75 | P22: =G22+O22 -> 8703.75 | Q22: ='5-Banka Listesi'!G23 -> 0 | R22: =G22-Q22 -> 8250 | S22: =ROUND(G22*0.0225,3) -> 185.625 | T22: =ROUND(G22*0.02,3) -> 165 | U22: =ROUND(Q22+R22+S22+T22,3) -> 8600.625 | V22: 18
B23: 19 | C23: ='!!!KATILIMCI LİSTESİ!!!'!B20 -> ABDURRAHMAN YAVUZ | D23: ='!!!KATILIMCI LİSTESİ!!!'!C20 -> 11516080912 | E23: ='!!! VERİLER !!!'!C1 -> 1375 | F23: ='1-Devamsızlık Formu (Ek-4)'!AJ25 -> 9 | G23: =IF(AND('1-Devamsızlık Formu (Ek-4)'!D25="",F23>0,'1-Devamsızlık Formu (Ek-4)'!AW25="KASIM 2024"),(E23*(F23-1)+(666.75)),E23*F23) -> 12375 | H23: =G23*0.01 -> 123.75 | I23: =G23*0.01 -> 123.75 | J23: =IF(G23>20002.5,(G23-H23-I23)-(17002.12),0) -> 0 | K23: =J23*0.15 -> 0 | L23: =ROUND(K23-M23,2) -> #REF! | M23: =IF(K23-'!!!KATILIMCI LİSTESİ!!!'!#REF!>0,'!!!KATILIMCI LİSTESİ!!!'!#REF!,K23) -> #REF! | N23: =G23*0.045 -> 556.875 | O23: =G23*0.055 -> 680.625 | P23: =G23+O23 -> 13055.625 | Q23: ='5-Banka Listesi'!G24 -> 0 | R23: =G23-Q23 -> 12375 | S23: =ROUND(G23*0.0225,3) -> 278.438 | T23: =ROUND(G23*0.02,3) -> 247.5 | U23: =ROUND(Q23+R23+S23+T23,3) -> 12900.938 | V23: 19
B24: 20 | C24: ='!!!KATILIMCI LİSTESİ!!!'!B21 -> ABDURRAHMAN EMRE COŞKUN | D24: ='!!!KATILIMCI LİSTESİ!!!'!C21 -> 58198589036 | E24: ='!!! VERİLER !!!'!C1 -> 1375 | F24: ='1-Devamsızlık Formu (Ek-4)'!AJ26 -> 12 | G24: =IF(AND('1-Devamsızlık Formu (Ek-4)'!D26="",F24>0,'1-Devamsızlık Formu (Ek-4)'!AW26="KASIM 2024"),(E24*(F24-1)+(666.75)),E24*F24) -> 16500 | H24: =G24*0.01 -> 165 | I24: =G24*0.01 -> 165 | J24: =IF(G24>20002.5,(G24-H24-I24)-(17002.12),0) -> 0 | K24: =J24*0.15 -> 0 | L24: =ROUND(K24-M24,2) -> #REF! | M24: =IF(K24-'!!!KATILIMCI LİSTESİ!!!'!#REF!>0,'!!!KATILIMCI LİSTESİ!!!'!#REF!,K24) -> #REF! | N24: =G24*0.045 -> 742.5 | O24: =G24*0.055 -> 907.5 | P24: =G24+O24 -> 17407.5 | Q24: ='5-Banka Listesi'!G25 -> 0 | R24: =G24-Q24 -> 16500 | S24: =ROUND(G24*0.0225,3) -> 371.25 | T24: =ROUND(G24*0.02,3) -> 330 | U24: =ROUND(Q24+R24+S24+T24,3) -> 17201.25 | V24: 20
